Workbook

Sheet Figure 3A
A1: Experimental conditions | F1: The values here have been normalized against the max intensity. For example, the intensity for 0% stain for the wavenumber of 399.924 was divided by the maximum intensity for that column, i.e. Sheet titled unstained biomass cell D4 was divided by D2 in the same sheet. Likewise, the remaining data was normalized.
A2: Daphnia magna was exposed to 750 nm PS at a concentration of 0.1 ppm. Histological slices were 20 µm thick. After acquiring a histological slice, the slice was stained with H&E stain at varrying concentrations (0%, 5%, 10%, 25%, 50%, 100%). | E2: Peak wavelenghts (nm) | F2: =VLOOKUP(F3,F5:N465,9,FALSE) -> 597.3769 | G2: =VLOOKUP(G3,G5:N465,8,FALSE) -> 615.2386 | H2: =VLOOKUP(H3,H5:N465,7,FALSE) -> 638.342 | I2: =VLOOKUP(I3,I5:O465,6,FALSE) -> 655.1245 | J2: =VLOOKUP(J3,J5:T465,5,FALSE) -> 683.7104 | K2: =VLOOKUP(K3,K5:Q465,4,FALSE) -> 657.7136
E3: maximum intensity (a.u.) | F3: =MAX(F5:F465) -> 1 | G3: =MAX(G5:G465) -> 1 | H3: =MAX(H5:H465) -> 1 | I3: =MAX(I5:I465) -> 1 | J3: =MAX(J5:J465) -> 1 | K3: =MAX(K5:K465) -> 1
E4: wavenumber (nm) | F4: 0 | G4: 0.05 | H4: 0.1 | I4: 0.25 | J4: 0.5 | K4: 1 | L4: PS | N4: this column here is used for the VLOOKUP function used in the following cells: C2 to H2. The VLOOKUP function was used to find the peak wavelength.
E5: 399.9241 | F5: ='unstained biomass'!D4/'unstained biomass'!$D$2 -> 0.0033871651 | G5: ='5 percent stain'!B3/'5 percent stain'!$B$1 -> 0.0019429828 | H5: ='10 percent stain'!B3/'10 percent stain'!$B$1 -> 0.0020189335 | I5: ='25 percent stain'!D3/'25 percent stain'!$D$1 -> 0.0049696849 | J5: ='50 percent stain'!D4/'50 percent stain'!$D$2 -> 0.001651405 | K5: ='100 percent stain'!B3/'100 percent stain'!$B$1 -> 0.0034796973 | L5: ='PS spectra'!D6/'PS spectra'!$D$4 -> 0.002272295 | N5: 399.9241
E6: 401.12 | F6: ='unstained biomass'!D5/'unstained biomass'!$D$2 -> 0.0047783221 | G6: ='5 percent stain'!B4/'5 percent stain'!$B$1 -> 0.0015350255 | H6: ='10 percent stain'!B4/'10 percent stain'!$B$1 -> 0.0027820711 | I6: ='25 percent stain'!D4/'25 percent stain'!$D$1 -> 0.0055021512 | J6: ='50 percent stain'!D5/'50 percent stain'!$D$2 -> 0.001188672 | K6: ='100 percent stain'!B4/'100 percent stain'!$B$1 -> 0.0030419143 | L6: ='PS spectra'!D7/'PS spectra'!$D$4 -> 0.0036637003 | N6: 401.12
E7: 402.3164 | F7: ='unstained biomass'!D6/'unstained biomass'!$D$2 -> 0.0056855985 | G7: ='5 percent stain'!B5/'5 percent stain'!$B$1 -> 0.0022887093 | H7: ='10 percent stain'!B5/'10 percent stain'!$B$1 -> 0.0017001546 | I7: ='25 percent stain'!D5/'25 percent stain'!$D$1 -> 0.00583583 | J7: ='50 percent stain'!D6/'50 percent stain'!$D$2 -> 0.001388199 | K7: ='100 percent stain'!B5/'100 percent stain'!$B$1 -> 0.003335274 | L7: ='PS spectra'!D8/'PS spectra'!$D$4 -> 0.0029830128 | N7: 402.3164
E8: 403.5133 | F8: ='unstained biomass'!D7/'unstained biomass'!$D$2 -> 0.0068045727 | G8: ='5 percent stain'!B6/'5 percent stain'!$B$1 -> 0.0010786666 | H8: ='10 percent stain'!B6/'10 percent stain'!$B$1 -> 0.0013330757 | I8: ='25 percent stain'!D6/'25 percent stain'!$D$1 -> 0.0053743593 | J8: ='50 percent stain'!D7/'50 percent stain'!$D$2 -> 0.0016301787 | K8: ='100 percent stain'!B6/'100 percent stain'!$B$1 -> 0.0033036814 | L8: ='PS spectra'!D9/'PS spectra'!$D$4 -> 0.0034935285 | N8: 403.5133
E9: 404.7106 | F9: ='unstained biomass'!D8/'unstained biomass'!$D$2 -> 0.0024798887 | G9: ='5 percent stain'!B7/'5 percent stain'!$B$1 -> 0.002454658 | H9: ='10 percent stain'!B7/'10 percent stain'!$B$1 -> 0.0016808346 | I9: ='25 percent stain'!D7/'25 percent stain'!$D$1 -> 0.0060914138 | J9: ='50 percent stain'!D8/'50 percent stain'!$D$2 -> 0.0022160241 | K9: ='100 percent stain'!B7/'100 percent stain'!$B$1 -> 0.0039400463 | L9: ='PS spectra'!D10/'PS spectra'!$D$4 -> 0.0033433768 | N9: 404.7106
E10: 405.9085 | F10: ='unstained biomass'!D9/'unstained biomass'!$D$2 -> 0.0031149822 | G10: ='5 percent stain'!B8/'5 percent stain'!$B$1 -> 0.0025514614 | H10: ='10 percent stain'!B8/'10 percent stain'!$B$1 -> 0.0022797527 | I10: ='25 percent stain'!D8/'25 percent stain'!$D$1 -> 0.0062476039 | J10: ='50 percent stain'!D9/'50 percent stain'!$D$2 -> 0.0020249876 | K10: ='100 percent stain'!B8/'100 percent stain'!$B$1 -> 0.0038046495 | L10: ='PS spectra'!D11/'PS spectra'!$D$4 -> 0.0044745193 | N10: 405.9085
E11: 407.1068 | F11: ='unstained biomass'!D10/'unstained biomass'!$D$2 -> 0.0059275389 | G11: ='5 percent stain'!B9/'5 percent stain'!$B$1 -> 0.002586034 | H11: ='10 percent stain'!B9/'10 percent stain'!$B$1 -> 0.0021638331 | I11: ='25 percent stain'!D9/'25 percent stain'!$D$1 -> 0.0066451787 | J11: ='50 percent stain'!D10/'50 percent stain'!$D$2 -> 0.0023646081 | K11: ='100 percent stain'!B9/'100 percent stain'!$B$1 -> 0.0039039405 | L11: ='PS spectra'!D12/'PS spectra'!$D$4 -> 0.0037037408 | N11: 407.1068
E12: 408.3056 | F12: ='unstained biomass'!D11/'unstained biomass'!$D$2 -> 0.0042339563 | G12: ='5 percent stain'!B10/'5 percent stain'!$B$1 -> 0.0028902733 | H12: ='10 percent stain'!B10/'10 percent stain'!$B$1 -> 0.0028786708 | I12: ='25 percent stain'!D10/'25 percent stain'!$D$1 -> 0.0068794638 | J12: ='50 percent stain'!D11/'50 percent stain'!$D$2 -> 0.0021650811 | K12: ='100 percent stain'!B10/'100 percent stain'!$B$1 -> 0.0040348241 | L12: ='PS spectra'!D13/'PS spectra'!$D$4 -> 0.0041942362 | N12: 408.3056
E13: 409.5049 | F13: ='unstained biomass'!D12/'unstained biomass'!$D$2 -> 0.0092844614 | G13: ='5 percent stain'!B11/'5 percent stain'!$B$1 -> 0.0024823161 | H13: ='10 percent stain'!B11/'10 percent stain'!$B$1 -> 0.0014586553 | I13: ='25 percent stain'!D11/'25 percent stain'!$D$1 -> 0.0067587715 | J13: ='50 percent stain'!D12/'50 percent stain'!$D$2 -> 0.0024877206 | K13: ='100 percent stain'!B11/'100 percent stain'!$B$1 -> 0.0050096809 | L13: ='PS spectra'!D14/'PS spectra'!$D$4 -> 0.0051552068 | N13: 409.5049
E14: 410.7047 | F14: ='unstained biomass'!D13/'unstained biomass'!$D$2 -> 0.0032359523 | G14: ='5 percent stain'!B12/'5 percent stain'!$B$1 -> 0.0018046922 | H14: ='10 percent stain'!B12/'10 percent stain'!$B$1 -> 0.0034099691 | I14: ='25 percent stain'!D12/'25 percent stain'!$D$1 -> 0.007901799 | J14: ='50 percent stain'!D13/'50 percent stain'!$D$2 -> 0.0027763981 | K14: ='100 percent stain'!B12/'100 percent stain'!$B$1 -> 0.0044996863 | L14: ='PS spectra'!D15/'PS spectra'!$D$4 -> 0.0037638014 | N14: 410.7047
E15: 411.9049 | F15: ='unstained biomass'!D14/'unstained biomass'!$D$2 -> 0.0055041432 | G15: ='5 percent stain'!B13/'5 percent stain'!$B$1 -> 0.0024754016 | H15: ='10 percent stain'!B13/'10 percent stain'!$B$1 -> 0.0035162287 | I15: ='25 percent stain'!D13/'25 percent stain'!$D$1 -> 0.0081289846 | J15: ='50 percent stain'!D14/'50 percent stain'!$D$2 -> 0.0027806433 | K15: ='100 percent stain'!B13/'100 percent stain'!$B$1 -> 0.005970998 | L15: ='PS spectra'!D16/'PS spectra'!$D$4 -> 0.0048448933 | N15: 411.9049
E16: 413.1056 | F16: ='unstained biomass'!D15/'unstained biomass'!$D$2 -> 0.007379181 | G16: ='5 percent stain'!B14/'5 percent stain'!$B$1 -> 0.0021089315 | H16: ='10 percent stain'!B14/'10 percent stain'!$B$1 -> 0.0031684699 | I16: ='25 percent stain'!D14/'25 percent stain'!$D$1 -> 0.0078734008 | J16: ='50 percent stain'!D15/'50 percent stain'!$D$2 -> 0.0023561176 | K16: ='100 percent stain'!B14/'100 percent stain'!$B$1 -> 0.0054655167 | L16: ='PS spectra'!D17/'PS spectra'!$D$4 -> 0.005355409 | N16: 413.1056
... E465: 999.6586 | F465: ='unstained biomass'!D464/'unstained biomass'!$D$2 -> 0.013155507 | G465: ='5 percent stain'!B463/'5 percent stain'!$B$1 -> 0.005967239 | H465: ='10 percent stain'!B463/'10 percent stain'!$B$1 -> 0.0066267388 | I465: ='25 percent stain'!D463/'25 percent stain'!$D$1 -> 0.010713221 | J465: ='50 percent stain'!D464/'50 percent stain'!$D$2 -> 0.021523453 | K465: ='100 percent stain'!B463/'100 percent stain'!$B$1 -> 0.018260512 | L465: ='PS spectra'!D466/'PS spectra'!$D$4 -> 0.013543679 | N465: 999.6586
L466: ='PS spectra'!D467/'PS spectra'!$D$4 -> 0

Sheet unstained biomass
C2: maximum intensity (a.u.) | D2: =MAX(D4:D464) -> 661.32
D3: Average intensity of 50 pixels for each wavelength (a.u.) | E3: Wavelength (nm) | F3: Raw spectra data from points on the image. All points are taken from biomass
D4: =AVERAGE(F4:BC4) -> 2.24 | E4: 399.9241 | F4: -1 | G4: -2 | H4: 11 | I4: 10 | J4: -1 | K4: 3 | L4: 0 | M4: -1 | N4: 4 | O4: 6 | P4: 3 | Q4: 8 | R4: -1 | S4: -12 | T4: 8 | U4: 4 | V4: 13 | W4: 1 | X4: 5 | Y4: -9 | Z4: -2 | AA4: -5 | AB4: -7 | AC4: 6 | AD4: -5 | AE4: 14 | AF4: 5 | AG4: 5 | AH4: -7 | AI4: 4 | AJ4: -6 | AK4: 2 | AL4: -1 | AM4: -3 | AN4: 21 | AO4: -10 | AP4: 4 | AQ4: 3 | AR4: 15 | AS4: 3 | AT4: 8 | AU4: -8 | AV4: -15 | AW4: 7 | AX4: 14 | AY4: -11 | AZ4: -8 | BA4: 16 | BB4: 20 | BC4: 4 | BD4: 9 | BE4: -1 | BF4: 10 | BG4: 5 | BH4: 4 | BI4: -6 | BJ4: 10 | BK4: 4 | BL4: -7 | BM4: 6 | BN4: 10 | BO4: 27 | BP4: -16 | BQ4: 29 | BR4: 0 | BS4: 7 | BT4: 13 | BU4: -3 | BV4: 2
D5: =AVERAGE(F5:BC5) -> 3.16 | E5: 401.12 | F5: 8 | G5: -7 | H5: -3 | I5: -3 | J5: 16 | K5: 6 | L5: -2 | M5: -2 | N5: -8 | O5: 14 | P5: 6 | Q5: 6 | R5: 1 | S5: 7 | T5: 7 | U5: 0 | V5: 1 | W5: -2 | X5: 2 | Y5: 13 | Z5: -3 | AA5: -7 | AB5: -7 | AC5: 0 | AD5: 4 | AE5: 17 | AF5: 3 | AG5: 4 | AH5: 1 | AI5: 16 | AJ5: 14 | AK5: -9 | AL5: 16 | AM5: 2 | AN5: 10 | AO5: 0 | AP5: -3 | AQ5: 1 | AR5: -8 | AS5: 2 | AT5: -11 | AU5: -1 | AV5: 8 | AW5: -3 | AX5: 5 | AY5: 13 | AZ5: 11 | BA5: 2 | BB5: 13 | BC5: 8 | BD5: 0 | BE5: 0 | BF5: -6 | BG5: 31 | BH5: -4 | BI5: -4 | BJ5: 14 | BK5: 17 | BL5: -14 | BM5: 2 | BN5: 15 | BO5: -7 | BP5: -8 | BQ5: -2 | BR5: -4 | BS5: 15 | BT5: 8 | BU5: 13 | BV5: 3
D6: =AVERAGE(F6:BC6) -> 3.76 | E6: 402.3164 | F6: -5 | G6: -5 | H6: 13 | I6: 25 | J6: 8 | K6: 13 | L6: 3 | M6: 2 | N6: 7 | O6: -3 | P6: 13 | Q6: 6 | R6: -10 | S6: 1 | T6: 1 | U6: 12 | V6: 6 | W6: -6 | X6: 5 | Y6: -3 | Z6: -2 | AA6: 7 | AB6: 6 | AC6: 3 | AD6: -18 | AE6: 3 | AF6: 13 | AG6: 2 | AH6: -2 | AI6: 13 | AJ6: 7 | AK6: -1 | AL6: 11 | AM6: -1 | AN6: -10 | AO6: 4 | AP6: -3 | AQ6: 6 | AR6: 9 | AS6: 11 | AT6: -13 | AU6: -1 | AV6: 6 | AW6: -3 | AX6: 18 | AY6: 6 | AZ6: 6 | BA6: 11 | BB6: 10 | BC6: 7 | BD6: -7 | BE6: 5 | BF6: -9 | BG6: -4 | BH6: 3 | BI6: 11 | BJ6: 7 | BK6: 17 | BL6: -11 | BM6: 7 | BN6: -3 | BO6: 1 | BP6: 13 | BQ6: 0 | BR6: 14 | BS6: 1 | BT6: 19 | BU6: 4 | BV6: -6
D7: =AVERAGE(F7:BC7) -> 4.5 | E7: 403.5133 | F7: -1 | G7: -6 | H7: 6 | I7: -6 | J7: 4 | K7: 15 | L7: 4 | M7: -14 | N7: 20 | O7: -1 | P7: 9 | Q7: 6 | R7: 0 | S7: 6 | T7: 8 | U7: 2 | V7: -1 | W7: 6 | X7: -12 | Y7: 7 | Z7: 15 | AA7: 16 | AB7: 1 | AC7: -4 | AD7: 15 | AE7: 9 | AF7: -4 | AG7: -7 | AH7: 24 | AI7: 9 | AJ7: 10 | AK7: 21 | AL7: 7 | AM7: 19 | AN7: 7 | AO7: 6 | AP7: 10 | AQ7: -6 | AR7: -8 | AS7: -11 | AT7: -7 | AU7: 12 | AV7: -2 | AW7: 7 | AX7: 0 | AY7: 16 | AZ7: 7 | BA7: 2 | BB7: 2 | BC7: 7 | BD7: -17 | BE7: 12 | BF7: 2 | BG7: 18 | BH7: 16 | BI7: -3 | BJ7: 0 | BK7: 6 | BL7: 3 | BM7: -7 | BN7: -11 | BO7: -7 | BP7: 1 | BQ7: -12 | BR7: 10 | BS7: 2 | BT7: -2 | BU7: -1 | BV7: 3
D8: =AVERAGE(F8:BC8) -> 1.64 | E8: 404.7106 | F8: -11 | G8: -14 | H8: 8 | I8: -8 | J8: 1 | K8: 9 | L8: 20 | M8: -4 | N8: -7 | O8: 16 | P8: 5 | Q8: -6 | R8: 7 | S8: 4 | T8: 0 | U8: 4 | V8: 8 | W8: -4 | X8: 13 | Y8: -10 | Z8: -6 | AA8: 0 | AB8: -8 | AC8: -11 | AD8: 0 | AE8: 6 | AF8: -18 | AG8: 3 | AH8: 19 | AI8: 15 | AJ8: 8 | AK8: 14 | AL8: -8 | AM8: -1 | AN8: 7 | AO8: -2 | AP8: -8 | AQ8: -3 | AR8: -1 | AS8: -6 | AT8: 1 | AU8: 10 | AV8: -10 | AW8: 12 | AX8: 23 | AY8: -5 | AZ8: 1 | BA8: 17 | BB8: 3 | BC8: -1 | BD8: 1 | BE8: 15 | BF8: 7 | BG8: 3 | BH8: 9 | BI8: 0 | BJ8: 10 | BK8: 8 | BL8: 9 | BM8: 12 | BN8: -6 | BO8: -4 | BP8: 24 | BQ8: 2 | BR8: 5 | BS8: 11 | BT8: 5 | BU8: 6 | BV8: 7
D9: =AVERAGE(F9:BC9) -> 2.06 | E9: 405.9085 | F9: -2 | G9: -6 | H9: 12 | I9: -12 | J9: 5 | K9: 10 | L9: -1 | M9: -6 | N9: -12 | O9: 6 | P9: 4 | Q9: 1 | R9: 7 | S9: -11 | T9: -9 | U9: -14 | V9: 9 | W9: 8 | X9: -1 | Y9: -8 | Z9: 1 | AA9: 0 | AB9: 4 | AC9: 1 | AD9: 10 | AE9: 6 | AF9: 16 | AG9: 13 | AH9: -4 | AI9: 8 | AJ9: 23 | AK9: 17 | AL9: -2 | AM9: -11 | AN9: 14 | AO9: 6 | AP9: 6 | AQ9: -5 | AR9: -2 | AS9: -1 | AT9: -2 | AU9: -3 | AV9: 4 | AW9: 5 | AX9: 5 | AY9: -1 | AZ9: 5 | BA9: 2 | BB9: -2 | BC9: 10 | BD9: -25 | BE9: 10 | BF9: 7 | BG9: -2 | BH9: 8 | BI9: -4 | BJ9: 6 | BK9: 9 | BL9: -4 | BM9: -1 | BN9: 13 | BO9: 5 | BP9: 2 | BQ9: 11 | BR9: 2 | BS9: -2 | BT9: -1 | BU9: 3 | BV9: -4
D10: =AVERAGE(F10:BC10) -> 3.92 | E10: 407.1068 | F10: -2 | G10: -6 | H10: 13 | I10: 26 | J10: 6 | K10: -6 | L10: 0 | M10: -5 | N10: 12 | O10: 8 | P10: 0 | Q10: 5 | R10: -8 | S10: 15 | T10: 2 | U10: -9 | V10: 16 | W10: -13 | X10: 9 | Y10: 5 | Z10: 20 | AA10: 0 | AB10: 4 | AC10: 6 | AD10: 14 | AE10: 8 | AF10: -2 | AG10: 0 | AH10: 11 | AI10: -11 | AJ10: 14 | AK10: -3 | AL10: 9 | AM10: 2 | AN10: 13 | AO10: 7 | AP10: -7 | AQ10: -3 | AR10: 2 | AS10: 2 | AT10: 12 | AU10: 3 | AV10: 4 | AW10: 16 | AX10: -13 | AY10: 1 | AZ10: -4 | BA10: 16 | BB10: 1 | BC10: 6 | BD10: 14 | BE10: 6 | BF10: 13 | BG10: -3 | BH10: 4 | BI10: 0 | BJ10: 1 | BK10: 3 | BL10: 12 | BM10: -9 | BN10: -3 | BO10: -7 | BP10: -7 | BQ10: 0 | BR10: -13 | BS10: 14 | BT10: -12 | BU10: -5 | BV10: 7
D11: =AVERAGE(F11:BC11) -> 2.8 | E11: 408.3056 | F11: -17 | G11: 3 | H11: -10 | I11: 16 | J11: -16 | K11: -3 | L11: -6 | M11: 9 | N11: 9 | O11: -1 | P11: 0 | Q11: 5 | R11: 10 | S11: 5 | T11: 8 | U11: -19 | V11: 14 | W11: 16 | X11: -1 | Y11: 9 | Z11: -6 | AA11: -13 | AB11: 6 | AC11: 13 | AD11: 5 | AE11: -7 | AF11: -1 | AG11: 4 | AH11: 23 | AI11: 0 | AJ11: 0 | AK11: -2 | AL11: 12 | AM11: -2 | AN11: -4 | AO11: -3 | AP11: 6 | AQ11: 9 | AR11: 4 | AS11: 15 | AT11: -10 | AU11: 14 | AV11: 10 | AW11: 9 | AX11: 3 | AY11: 3 | AZ11: 11 | BA11: 6 | BB11: -1 | BC11: 5 | BD11: -4 | BE11: 2 | BF11: 12 | BG11: -3 | BH11: 10 | BI11: 8 | BJ11: 9 | BK11: 11 | BL11: -6 | BM11: 9 | BN11: -16 | BO11: -3 | BP11: -7 | BQ11: 8 | BR11: 4 | BS11: 5 | BT11: 7 | BU11: -5 | BV11: 3
D12: =AVERAGE(F12:BC12) -> 6.14 | E12: 409.5049 | F12: 24 | G12: 12 | H12: 5 | I12: -8 | J12: 6 | K12: 1 | L12: 4 | M12: 14 | N12: 7 | O12: 12 | P12: 2 | Q12: 2 | R12: 10 | S12: 15 | T12: 12 | U12: -6 | V12: 7 | W12: -1 | X12: 6 | Y12: 15 | Z12: 11 | AA12: 7 | AB12: 9 | AC12: -5 | AD12: -17 | AE12: 20 | AF12: 2 | AG12: 8 | AH12: 0 | AI12: -7 | AJ12: 0 | AK12: 12 | AL12: 21 | AM12: 2 | AN12: 0 | AO12: 8 | AP12: 14 | AQ12: 15 | AR12: 2 | AS12: 18 | AT12: -18 | AU12: 8 | AV12: 7 | AW12: 14 | AX12: -3 | AY12: 7 | AZ12: 10 | BA12: 7 | BB12: 14 | BC12: 2 | BD12: 3 | BE12: 6 | BF12: 0 | BG12: 10 | BH12: -4 | BI12: 15 | BJ12: 10 | BK12: -18 | BL12: 14 | BM12: -6 | BN12: -6 | BO12: 16 | BP12: 14 | BQ12: 13 | BR12: 13 | BS12: -2 | BT12: 12 | BU12: -2 | BV12: -21
D13: =AVERAGE(F13:BC13) -> 2.14 | E13: 410.7047 | F13: 0 | G13: 18 | H13: 5 | I13: 12 | J13: 4 | K13: 9 | L13: 1 | M13: 2 | N13: -1 | O13: 10 | P13: 9 | Q13: -21 | R13: 5 | S13: -1 | T13: -8 | U13: 4 | V13: -11 | W13: 12 | X13: 0 | Y13: -10 | Z13: 12 | AA13: -2 | AB13: -6 | AC13: 1 | AD13: -14 | AE13: -1 | AF13: -9 | AG13: -6 | AH13: -3 | AI13: 11 | AJ13: -2 | AK13: -3 | AL13: 5 | AM13: 0 | AN13: 7 | AO13: 36 | AP13: -3 | AQ13: -2 | AR13: 0 | AS13: 10 | AT13: 1 | AU13: 16 | AV13: -6 | AW13: 1 | AX13: 3 | AY13: 10 | AZ13: 12 | BA13: -6 | BB13: 0 | BC13: 6 | BD13: 13 | BE13: -6 | BF13: 11 | BG13: 9 | BH13: -3 | BI13: -1 | BJ13: -1 | BK13: 10 | BL13: 3 | BM13: 8 | BN13: 10 | BO13: 8 | BP13: -8 | BQ13: 5 | BR13: 0 | BS13: 14 | BT13: 15 | BU13: 2 | BV13: -10
D14: =AVERAGE(F14:BC14) -> 3.64 | E14: 411.9049 | F14: 5 | G14: -9 | H14: -10 | I14: -8 | J14: -1 | K14: 5 | L14: -4 | M14: 9 | N14: 5 | O14: 14 | P14: -1 | Q14: 2 | R14: -11 | S14: 7 | T14: 5 | U14: 7 | V14: 6 | W14: 4 | X14: 13 | Y14: -5 | Z14: -11 | AA14: -2 | AB14: -3 | AC14: -13 | AD14: 5 | AE14: 19 | AF14: 16 | AG14: 13 | AH14: -1 | AI14: 19 | AJ14: 5 | AK14: 15 | AL14: 12 | AM14: 0 | AN14: -12 | AO14: -2 | AP14: 23 | AQ14: 0 | AR14: 3 | AS14: 6 | AT14: 6 | AU14: 14 | AV14: -6 | AW14: -2 | AX14: -4 | AY14: -2 | AZ14: 22 | BA14: 16 | BB14: 8 | BC14: 5 | BD14: 9 | BE14: -7 | BF14: -10 | BG14: 1 | BH14: 15 | BI14: -1 | BJ14: -11 | BK14: 13 | BL14: -6 | BM14: 7 | BN14: 19 | BO14: 3 | BP14: 1 | BQ14: -2 | BR14: -11 | BS14: 8 | BT14: 5 | BU14: 2 | BV14: 11
D15: =AVERAGE(F15:BC15) -> 4.88 | E15: 413.1056 | F15: 0 | G15: -13 | H15: 11 | I15: 2 | J15: -8 | K15: 3 | L15: 20 | M15: 4 | N15: 10 | O15: 4 | P15: 4 | Q15: -4 | R15: 1 | S15: -5 | T15: -1 | U15: -9 | V15: 0 | W15: -9 | X15: -9 | Y15: -5 | Z15: -17 | AA15: 12 | AB15: -6 | AC15: 14 | AD15: 12 | AE15: 24 | AF15: 23 | AG15: 9 | AH15: 6 | AI15: 14 | AJ15: 2 | AK15: 23 | AL15: 20 | AM15: 18 | AN15: -10 | AO15: 5 | AP15: 12 | AQ15: 11 | AR15: 8 | AS15: 0 | AT15: 3 | AU15: 12 | AV15: 4 | AW15: 7 | AX15: 21 | AY15: 13 | AZ15: 0 | BA15: 0 | BB15: 9 | BC15: -1 | BD15: 2 | BE15: 10 | BF15: 13 | BG15: 4 | BH15: 1 | BI15: 1 | BJ15: 3 | BK15: -7 | BL15: -8 | BM15: -3 | BN15: 3 | BO15: -1 | BP15: 18 | BQ15: 8 | BR15: 18 | BS15: 2 | BT15: 8 | BU15: 19 | BV15: 2
... D464: =AVERAGE(F464:BC464) -> 8.7 | E464: 999.6586 | F464: 12 | G464: 18 | H464: -10 | I464: -1 | J464: 2 | K464: 6 | L464: 6 | M464: 23 | N464: 0 | O464: 29 | P464: -15 | Q464: 4 | R464: 7 | S464: 4 | T464: 9 | U464: -11 | V464: 8 | W464: 17 | X464: 6 | Y464: 5 | Z464: 13 | AA464: 5 | AB464: 10 | AC464: 9 | AD464: -2 | AE464: 23 | AF464: 19 | AG464: 10 | AH464: 24 | AI464: 37 | AJ464: 18 | AK464: 0 | AL464: 2 | AM464: 13 | AN464: 8 | AO464: 10 | AP464: 10 | AQ464: 2 | AR464: 1 | AS464: -4 | AT464: -1 | AU464: -11 | AV464: 0 | AW464: 12 | AX464: -15 | AY464: 5 | AZ464: 19 | BA464: 27 | BB464: 40 | BC464: 32 | BD464: 20 | BE464: -5 | BF464: 12 | BG464: 11 | BH464: -2 | BI464: 28 | BJ464: 3 | BK464: 15 | BL464: 9 | BM464: 3 | BN464: 8 | BO464: 11 | BP464: 10 | BQ464: 14 | BR464: 9 | BS464: 24 | BT464: 9 | BU464: 1 | BV464: 16

Sheet 5 percent stain
A1: maximum intensity (a.u.) | B1: =MAX(B3:B463) -> 2892.46
B2: Average intensity of 50 pixels for each wavelength (a.u.) | C2: Wavelength (nm) | D2: Raw spectra data from points on the image. All points are taken from biomass
B3: =AVERAGE(D3:BA3) -> 5.62 | C3: 399.9241 | D3: 22 | E3: -2 | F3: 15 | G3: 4 | H3: 4 | I3: 15 | J3: 7 | K3: 7 | L3: -3 | M3: 10 | N3: 12 | O3: 3 | P3: -11 | Q3: 11 | R3: 10 | S3: 3 | T3: -2 | U3: 10 | V3: 5 | W3: 5 | X3: 15 | Y3: 4 | Z3: 15 | AA3: 23 | AB3: 4 | AC3: 9 | AD3: -2 | AE3: 1 | AF3: 18 | AG3: 13 | AH3: -9 | AI3: -13 | AJ3: 0 | AK3: 12 | AL3: 7 | AM3: 3 | AN3: 13 | AO3: 15 | AP3: 1 | AQ3: 14 | AR3: 7 | AS3: 17 | AT3: -4 | AU3: -11 | AV3: 14 | AW3: 0 | AX3: -6 | AY3: -1 | AZ3: -4 | BA3: 1 | BB3: 13 | BC3: 6 | BD3: 5 | BE3: 1 | BF3: -1 | BG3: 15 | BH3: 7 | BI3: 16 | BJ3: 15
B4: =AVERAGE(D4:BA4) -> 4.44 | C4: 401.12 | D4: 6 | E4: -3 | F4: 0 | G4: 14 | H4: 2 | I4: 17 | J4: -1 | K4: 5 | L4: 3 | M4: 3 | N4: -4 | O4: -4 | P4: -2 | Q4: 2 | R4: 5 | S4: 1 | T4: 3 | U4: 1 | V4: 4 | W4: 2 | X4: 1 | Y4: 2 | Z4: 2 | AA4: -9 | AB4: 1 | AC4: 16 | AD4: -1 | AE4: 12 | AF4: 7 | AG4: 10 | AH4: -7 | AI4: -13 | AJ4: 7 | AK4: 23 | AL4: 12 | AM4: 21 | AN4: 10 | AO4: 12 | AP4: -13 | AQ4: 10 | AR4: 16 | AS4: 7 | AT4: -15 | AU4: 14 | AV4: 17 | AW4: 1 | AX4: -7 | AY4: -5 | AZ4: 8 | BA4: 29 | BB4: 12 | BC4: 10 | BD4: 5 | BE4: -1 | BF4: 0 | BG4: 0 | BH4: -3 | BI4: 3 | BJ4: 15
B5: =AVERAGE(D5:BA5) -> 6.62 | C5: 402.31641 | D5: 5 | E5: 5 | F5: 3 | G5: 18 | H5: 13 | I5: -2 | J5: 6 | K5: 28 | L5: 3 | M5: 21 | N5: 1 | O5: -4 | P5: 5 | Q5: 2 | R5: 21 | S5: -1 | T5: 5 | U5: -3 | V5: -16 | W5: 7 | X5: 18 | Y5: -6 | Z5: 0 | AA5: 7 | AB5: -4 | AC5: 6 | AD5: 20 | AE5: 7 | AF5: 15 | AG5: 14 | AH5: 5 | AI5: 8 | AJ5: 6 | AK5: 8 | AL5: -12 | AM5: 9 | AN5: 14 | AO5: 16 | AP5: 14 | AQ5: 7 | AR5: 11 | AS5: 9 | AT5: -1 | AU5: 8 | AV5: 11 | AW5: 13 | AX5: 3 | AY5: 2 | AZ5: -2 | BA5: 8 | BB5: -7 | BC5: 8 | BD5: 0 | BE5: -13 | BF5: -11 | BG5: 5 | BH5: 0 | BI5: -10 | BJ5: 13
B6: =AVERAGE(D6:BA6) -> 3.12 | C6: 403.51331 | D6: -1 | E6: -3 | F6: 7 | G6: -9 | H6: 13 | I6: 32 | J6: 4 | K6: -12 | L6: 8 | M6: 1 | N6: 8 | O6: 1 | P6: 5 | Q6: 2 | R6: -8 | S6: -9 | T6: 2 | U6: 0 | V6: 12 | W6: -3 | X6: 17 | Y6: 2 | Z6: 1 | AA6: 0 | AB6: 8 | AC6: 4 | AD6: -7 | AE6: 14 | AF6: 21 | AG6: -12 | AH6: 6 | AI6: -10 | AJ6: 14 | AK6: 15 | AL6: 7 | AM6: -19 | AN6: -12 | AO6: 8 | AP6: -15 | AQ6: 16 | AR6: -3 | AS6: 5 | AT6: 9 | AU6: 6 | AV6: 16 | AW6: -3 | AX6: -1 | AY6: 1 | AZ6: 8 | BA6: 10 | BB6: -1 | BC6: 0 | BD6: 5 | BE6: -9 | BF6: 6 | BG6: -5 | BH6: 17 | BI6: 6 | BJ6: 11
B7: =AVERAGE(D7:BA7) -> 7.1 | C7: 404.7106 | D7: 16 | E7: 18 | F7: 17 | G7: 2 | H7: 11 | I7: 17 | J7: -3 | K7: 3 | L7: 1 | M7: 3 | N7: -6 | O7: 6 | P7: 29 | Q7: -3 | R7: 2 | S7: 12 | T7: 9 | U7: 34 | V7: -8 | W7: 10 | X7: 9 | Y7: 4 | Z7: 7 | AA7: 16 | AB7: -5 | AC7: 22 | AD7: 6 | AE7: 7 | AF7: 2 | AG7: 7 | AH7: -6 | AI7: 19 | AJ7: 12 | AK7: -7 | AL7: 6 | AM7: -11 | AN7: 7 | AO7: 16 | AP7: -4 | AQ7: 5 | AR7: 7 | AS7: 5 | AT7: 8 | AU7: 1 | AV7: 17 | AW7: 9 | AX7: 5 | AY7: 2 | AZ7: 13 | BA7: 6 | BB7: 3 | BC7: 4 | BD7: -1 | BE7: -5 | BF7: -1 | BG7: -20 | BH7: 9 | BI7: -10 | BJ7: -3
B8: =AVERAGE(D8:BA8) -> 7.38 | C8: 405.90851 | D8: 7 | E8: 19 | F8: 9 | G8: 6 | H8: 9 | I8: 21 | J8: 8 | K8: 14 | L8: 6 | M8: -11 | N8: 7 | O8: -1 | P8: 11 | Q8: 21 | R8: 11 | S8: 10 | T8: -7 | U8: 4 | V8: 3 | W8: 14 | X8: 7 | Y8: -14 | Z8: -15 | AA8: 3 | AB8: 9 | AC8: 13 | AD8: 2 | AE8: 1 | AF8: -6 | AG8: 5 | AH8: 8 | AI8: -8 | AJ8: 11 | AK8: 17 | AL8: 26 | AM8: 15 | AN8: 5 | AO8: 12 | AP8: 5 | AQ8: 15 | AR8: 15 | AS8: -2 | AT8: 10 | AU8: 16 | AV8: 18 | AW8: 7 | AX8: 12 | AY8: 1 | AZ8: 12 | BA8: 8 | BB8: 6 | BC8: 7 | BD8: 5 | BE8: 15 | BF8: 17 | BG8: 5 | BH8: 15 | BI8: 21 | BJ8: 17
B9: =AVERAGE(D9:BA9) -> 7.48 | C9: 407.10681 | D9: 17 | E9: 12 | F9: 32 | G9: 0 | H9: 12 | I9: 27 | J9: 5 | K9: -3 | L9: 21 | M9: -4 | N9: 9 | O9: 17 | P9: 5 | Q9: -6 | R9: 0 | S9: 8 | T9: -3 | U9: 10 | V9: 2 | W9: 5 | X9: -3 | Y9: 10 | Z9: 3 | AA9: 5 | AB9: 9 | AC9: 2 | AD9: 16 | AE9: -3 | AF9: 17 | AG9: 15 | AH9: 4 | AI9: 7 | AJ9: -13 | AK9: 0 | AL9: 10 | AM9: 9 | AN9: 15 | AO9: 5 | AP9: 18 | AQ9: 7 | AR9: -8 | AS9: 14 | AT9: 6 | AU9: 4 | AV9: 1 | AW9: 27 | AX9: 1 | AY9: 5 | AZ9: 9 | BA9: 16 | BB9: 4 | BC9: 10 | BD9: -8 | BE9: -7 | BF9: 4 | BG9: 2 | BH9: 6 | BI9: -1 | BJ9: 7
B10: =AVERAGE(D10:BA10) -> 8.36 | C10: 408.3056 | D10: 9 | E10: 28 | F10: 8 | G10: 11 | H10: 14 | I10: 19 | J10: 29 | K10: 15 | L10: 15 | M10: 0 | N10: 18 | O10: 19 | P10: 12 | Q10: 17 | R10: 0 | S10: -4 | T10: -4 | U10: 9 | V10: 20 | W10: 6 | X10: 9 | Y10: -2 | Z10: -2 | AA10: -3 | AB10: 9 | AC10: 18 | AD10: -5 | AE10: 14 | AF10: 3 | AG10: 11 | AH10: 0 | AI10: 3 | AJ10: 0 | AK10: -6 | AL10: -2 | AM10: 8 | AN10: 11 | AO10: 10 | AP10: 3 | AQ10: 4 | AR10: 29 | AS10: 18 | AT10: -3 | AU10: -1 | AV10: 2 | AW10: 12 | AX10: 9 | AY10: 7 | AZ10: 12 | BA10: 9 | BB10: 17 | BC10: 1 | BD10: -2 | BE10: 0 | BF10: -5 | BG10: 13 | BH10: -5 | BI10: 5 | BJ10: 13
B11: =AVERAGE(D11:BA11) -> 7.18 | C11: 409.50491 | D11: 10 | E11: 1 | F11: 9 | G11: 16 | H11: 10 | I11: 18 | J11: 26 | K11: 5 | L11: 10 | M11: 5 | N11: 9 | O11: 10 | P11: -9 | Q11: 16 | R11: 11 | S11: 12 | T11: 21 | U11: 3 | V11: 4 | W11: 12 | X11: 4 | Y11: -4 | Z11: -4 | AA11: 3 | AB11: 2 | AC11: -7 | AD11: 0 | AE11: 4 | AF11: 19 | AG11: 9 | AH11: -1 | AI11: -9 | AJ11: 8 | AK11: 14 | AL11: 6 | AM11: 2 | AN11: 9 | AO11: 3 | AP11: -9 | AQ11: 13 | AR11: 17 | AS11: 7 | AT11: 11 | AU11: 3 | AV11: 17 | AW11: 17 | AX11: 5 | AY11: 0 | AZ11: 10 | BA11: 11 | BB11: 1 | BC11: 12 | BD11: 10 | BE11: 8 | BF11: 0 | BG11: 2 | BH11: 8 | BI11: -9 | BJ11: 0
B12: =AVERAGE(D12:BA12) -> 5.22 | C12: 410.70471 | D12: 10 | E12: 7 | F12: 18 | G12: -5 | H12: 14 | I12: 24 | J12: 1 | K12: -9 | L12: 1 | M12: -2 | N12: 27 | O12: 19 | P12: -13 | Q12: 17 | R12: -7 | S12: 0 | T12: -4 | U12: -11 | V12: 9 | W12: 0 | X12: 12 | Y12: -10 | Z12: -10 | AA12: -7 | AB12: 18 | AC12: 5 | AD12: -3 | AE12: 27 | AF12: 8 | AG12: 9 | AH12: 5 | AI12: 0 | AJ12: 4 | AK12: 3 | AL12: 2 | AM12: 6 | AN12: 9 | AO12: -3 | AP12: 10 | AQ12: -12 | AR12: -4 | AS12: 10 | AT12: 15 | AU12: 12 | AV12: 10 | AW12: 6 | AX12: 10 | AY12: 17 | AZ12: 0 | BA12: 16 | BB12: 2 | BC12: 7 | BD12: -3 | BE12: -3 | BF12: 10 | BG12: 18 | BH12: 22 | BI12: 15 | BJ12: 2
B13: =AVERAGE(D13:BA13) -> 7.16 | C13: 411.90491 | D13: 15 | E13: 6 | F13: 6 | G13: -12 | H13: 14 | I13: 31 | J13: 11 | K13: -6 | L13: 20 | M13: 32 | N13: -2 | O13: 21 | P13: 4 | Q13: 5 | R13: 3 | S13: 3 | T13: 3 | U13: -1 | V13: 25 | W13: 18 | X13: 18 | Y13: -4 | Z13: -3 | AA13: 5 | AB13: -7 | AC13: 1 | AD13: 10 | AE13: -1 | AF13: 27 | AG13: 8 | AH13: -2 | AI13: 2 | AJ13: 4 | AK13: 11 | AL13: 5 | AM13: 12 | AN13: 8 | AO13: 10 | AP13: -1 | AQ13: 2 | AR13: 2 | AS13: 5 | AT13: 14 | AU13: 1 | AV13: 11 | AW13: 7 | AX13: 10 | AY13: 6 | AZ13: 0 | BA13: 1 | BB13: 10 | BC13: -1 | BD13: 20 | BE13: 0 | BF13: 7 | BG13: 4 | BH13: 12 | BI13: -16 | BJ13: -5
B14: =AVERAGE(D14:BA14) -> 6.1 | C14: 413.10559 | D14: 19 | E14: 4 | F14: 9 | G14: 6 | H14: -4 | I14: 24 | J14: 15 | K14: 6 | L14: -9 | M14: 9 | N14: 15 | O14: -14 | P14: 3 | Q14: -7 | R14: 16 | S14: 12 | T14: 5 | U14: 8 | V14: -6 | W14: 7 | X14: 20 | Y14: 4 | Z14: 6 | AA14: -7 | AB14: 13 | AC14: 14 | AD14: 10 | AE14: -8 | AF14: 15 | AG14: 0 | AH14: -4 | AI14: 11 | AJ14: -8 | AK14: -7 | AL14: 11 | AM14: 26 | AN14: 0 | AO14: 8 | AP14: 0 | AQ14: 12 | AR14: 0 | AS14: -3 | AT14: 5 | AU14: 5 | AV14: 17 | AW14: 1 | AX14: 5 | AY14: 31 | AZ14: 6 | BA14: 4 | BB14: -5 | BC14: 8 | BD14: 9 | BE14: 2 | BF14: 16 | BG14: 2 | BH14: 21 | BI14: 0 | BJ14: 10
... B463: =AVERAGE(D463:BA463) -> 17.26 | C463: 999.65863 | D463: 30 | E463: 28 | F463: 32 | G463: 6 | H463: 42 | I463: 24 | J463: 7 | K463: 6 | L463: -6 | M463: 17 | N463: 47 | O463: 45 | P463: 37 | Q463: 35 | R463: 2 | S463: 50 | T463: -16 | U463: 3 | V463: 6 | W463: -5 | X463: 15 | Y463: 13 | Z463: 4 | AA463: 1 | AB463: 32 | AC463: 46 | AD463: 19 | AE463: 30 | AF463: 40 | AG463: 11 | AH463: 5 | AI463: -6 | AJ463: 19 | AK463: 26 | AL463: 35 | AM463: 25 | AN463: 11 | AO463: 22 | AP463: -1 | AQ463: 27 | AR463: 34 | AS463: 11 | AT463: -8 | AU463: -1 | AV463: -5 | AW463: 13 | AX463: 14 | AY463: 3 | AZ463: 13 | BA463: 25 | BB463: 8 | BC463: 15 | BD463: 11 | BE463: 3 | BF463: 27 | BG463: 8 | BH463: 25 | BI463: 8 | BJ463: 10

Sheet 10 percent stain
A1: maximum intensity (a.u.) | B1: =MAX(B3:B463) -> 2070.4
B2: Average intensity of 50 pixels for each wavelength (a.u.) | C2: Wavelength (nm) | D2: Raw spectra data from points on the image. All points are taken from biomass
B3: =AVERAGE(D3:BA3) -> 4.18 | C3: 399.9241 | D3: 7 | E3: -4 | F3: 13 | G3: -2 | H3: 1 | I3: -13 | J3: 11 | K3: 5 | L3: 13 | M3: -9 | N3: 7 | O3: 18 | P3: -1 | Q3: 14 | R3: -5 | S3: 5 | T3: 8 | U3: -8 | V3: -5 | W3: 0 | X3: 11 | Y3: 12 | Z3: 12 | AA3: 1 | AB3: -2 | AC3: 5 | AD3: 12 | AE3: -12 | AF3: -3 | AG3: 8 | AH3: 0 | AI3: -5 | AJ3: -4 | AK3: 7 | AL3: -5 | AM3: 6 | AN3: 24 | AO3: 19 | AP3: 5 | AQ3: 6 | AR3: 6 | AS3: -5 | AT3: 2 | AU3: -16 | AV3: 5 | AW3: 1 | AX3: 23 | AY3: 12 | AZ3: 18 | BA3: 11 | BB3: 4 | BC3: 0 | BD3: 12 | BE3: 4 | BF3: 2 | BG3: -2 | BH3: -6 | BI3: 7 | BJ3: 7 | BK3: 18 | BL3: 5 | BM3: 16 | BN3: 12 | BO3: 5 | BP3: 23 | BQ3: -2
B4: =AVERAGE(D4:BA4) -> 5.76 | C4: 401.12 | D4: 12 | E4: 3 | F4: -15 | G4: 15 | H4: 18 | I4: 8 | J4: -3 | K4: 17 | L4: -4 | M4: -6 | N4: 6 | O4: 18 | P4: 2 | Q4: -2 | R4: 2 | S4: 11 | T4: -1 | U4: 4 | V4: 2 | W4: 5 | X4: -9 | Y4: 6 | Z4: -4 | AA4: -9 | AB4: 4 | AC4: -9 | AD4: 12 | AE4: -7 | AF4: 9 | AG4: -6 | AH4: 10 | AI4: 17 | AJ4: 18 | AK4: 20 | AL4: 7 | AM4: 14 | AN4: 19 | AO4: -1 | AP4: 12 | AQ4: -3 | AR4: 4 | AS4: 6 | AT4: -10 | AU4: 19 | AV4: 24 | AW4: -9 | AX4: 10 | AY4: 16 | AZ4: 25 | BA4: 11 | BB4: 18 | BC4: 3 | BD4: -6 | BE4: -12 | BF4: 10 | BG4: 12 | BH4: 4 | BI4: 2 | BJ4: 6 | BK4: 8 | BL4: 8 | BM4: 12 | BN4: -4 | BO4: 27 | BP4: 8 | BQ4: 2
B5: =AVERAGE(D5:BA5) -> 3.52 | C5: 402.31641 | D5: 8 | E5: 13 | F5: 28 | G5: -8 | H5: 22 | I5: 15 | J5: 8 | K5: 20 | L5: -8 | M5: -7 | N5: -9 | O5: 0 | P5: 15 | Q5: -23 | R5: 10 | S5: -7 | T5: 20 | U5: 10 | V5: -6 | W5: 2 | X5: 12 | Y5: -5 | Z5: -11 | AA5: 16 | AB5: -3 | AC5: -4 | AD5: -3 | AE5: 13 | AF5: 10 | AG5: -13 | AH5: -4 | AI5: -19 | AJ5: 14 | AK5: -2 | AL5: -1 | AM5: 12 | AN5: -4 | AO5: 18 | AP5: 20 | AQ5: 7 | AR5: 8 | AS5: 1 | AT5: 3 | AU5: -9 | AV5: -10 | AW5: -4 | AX5: 6 | AY5: 15 | AZ5: 5 | BA5: 5 | BB5: 11 | BC5: -6 | BD5: 14 | BE5: -2 | BF5: 5 | BG5: -4 | BH5: 14 | BI5: -4 | BJ5: 17 | BK5: 24 | BL5: 8 | BM5: 15 | BN5: 7 | BO5: 2 | BP5: 6 | BQ5: 26
B6: =AVERAGE(D6:BA6) -> 2.76 | C6: 403.51331 | D6: -2 | E6: -20 | F6: -13 | G6: -7 | H6: 8 | I6: 4 | J6: 4 | K6: 11 | L6: 2 | M6: 17 | N6: 7 | O6: 3 | P6: 12 | Q6: -10 | R6: 12 | S6: 4 | T6: 10 | U6: 9 | V6: -3 | W6: 14 | X6: 1 | Y6: 8 | Z6: -21 | AA6: 3 | AB6: 4 | AC6: 6 | AD6: -5 | AE6: -7 | AF6: 15 | AG6: 0 | AH6: 7 | AI6: 4 | AJ6: 6 | AK6: 5 | AL6: -5 | AM6: 17 | AN6: 23 | AO6: 9 | AP6: 10 | AQ6: 7 | AR6: -6 | AS6: -21 | AT6: -4 | AU6: -11 | AV6: 4 | AW6: 10 | AX6: 7 | AY6: 7 | AZ6: 7 | BA6: -4 | BB6: 0 | BC6: 14 | BD6: 8 | BE6: -2 | BF6: 11 | BG6: 16 | BH6: 6 | BI6: -2 | BJ6: 15 | BK6: 24 | BL6: 1 | BM6: 21 | BN6: 4 | BO6: 9 | BP6: 8 | BQ6: -3
B7: =AVERAGE(D7:BA7) -> 3.48 | C7: 404.7106 | D7: 1 | E7: -8 | F7: 12 | G7: 2 | H7: 4 | I7: 6 | J7: 11 | K7: -7 | L7: 10 | M7: 15 | N7: 9 | O7: 3 | P7: 8 | Q7: 6 | R7: -8 | S7: 14 | T7: -2 | U7: 12 | V7: 5 | W7: 12 | X7: 5 | Y7: -1 | Z7: 10 | AA7: 0 | AB7: 1 | AC7: -8 | AD7: 6 | AE7: 14 | AF7: -8 | AG7: 6 | AH7: 3 | AI7: 7 | AJ7: -8 | AK7: -3 | AL7: 9 | AM7: 3 | AN7: 13 | AO7: 20 | AP7: -6 | AQ7: 2 | AR7: -6 | AS7: -10 | AT7: -12 | AU7: -4 | AV7: 10 | AW7: 6 | AX7: 0 | AY7: 8 | AZ7: 7 | BA7: 5 | BB7: -3 | BC7: 8 | BD7: 3 | BE7: 0 | BF7: 11 | BG7: 1 | BH7: 16 | BI7: 24 | BJ7: 13 | BK7: 16 | BL7: 17 | BM7: 19 | BN7: 4 | BO7: 15 | BP7: 16 | BQ7: -8
B8: =AVERAGE(D8:BA8) -> 4.72 | C8: 405.90851 | D8: 1 | E8: 6 | F8: 12 | G8: 10 | H8: 11 | I8: 10 | J8: 25 | K8: -10 | L8: 12 | M8: -3 | N8: -3 | O8: -6 | P8: -2 | Q8: 8 | R8: 4 | S8: 3 | T8: 5 | U8: 3 | V8: 3 | W8: 14 | X8: -10 | Y8: 1 | Z8: 4 | AA8: 3 | AB8: 9 | AC8: 5 | AD8: 1 | AE8: 1 | AF8: 3 | AG8: 1 | AH8: 13 | AI8: -3 | AJ8: -5 | AK8: 11 | AL8: 8 | AM8: 11 | AN8: 12 | AO8: 15 | AP8: 0 | AQ8: 18 | AR8: 10 | AS8: -16 | AT8: 12 | AU8: -3 | AV8: -3 | AW8: 7 | AX8: 19 | AY8: 7 | AZ8: 5 | BA8: -3 | BB8: 3 | BC8: 1 | BD8: -17 | BE8: 21 | BF8: 20 | BG8: 20 | BH8: 17 | BI8: 21 | BJ8: -13 | BK8: 1 | BL8: -10 | BM8: 9 | BN8: 6 | BO8: 6 | BP8: 3 | BQ8: 4
B9: =AVERAGE(D9:BA9) -> 4.48 | C9: 407.10681 | D9: 3 | E9: 6 | F9: 4 | G9: 4 | H9: 4 | I9: 14 | J9: 5 | K9: 14 | L9: 5 | M9: -2 | N9: 22 | O9: -14 | P9: -8 | Q9: 6 | R9: 11 | S9: -7 | T9: 2 | U9: 19 | V9: 4 | W9: 17 | X9: 0 | Y9: -6 | Z9: 7 | AA9: 0 | AB9: 25 | AC9: -3 | AD9: 1 | AE9: 15 | AF9: 10 | AG9: 10 | AH9: -12 | AI9: -6 | AJ9: -11 | AK9: 5 | AL9: 5 | AM9: 13 | AN9: -5 | AO9: 2 | AP9: 14 | AQ9: 12 | AR9: 18 | AS9: 11 | AT9: 1 | AU9: -2 | AV9: 6 | AW9: 7 | AX9: -11 | AY9: -9 | AZ9: 8 | BA9: 10 | BB9: 9 | BC9: 5 | BD9: 2 | BE9: 15 | BF9: 2 | BG9: 8 | BH9: -4 | BI9: 13 | BJ9: 18 | BK9: -5 | BL9: 8 | BM9: 19 | BN9: 13 | BO9: 13 | BP9: 6 | BQ9: 2
B10: =AVERAGE(D10:BA10) -> 5.96 | C10: 408.3056 | D10: 9 | E10: 0 | F10: -7 | G10: 14 | H10: 0 | I10: 20 | J10: 5 | K10: 9 | L10: -7 | M10: 5 | N10: 9 | O10: 5 | P10: -13 | Q10: -1 | R10: 15 | S10: 0 | T10: 13 | U10: 17 | V10: 22 | W10: -6 | X10: 29 | Y10: -3 | Z10: 5 | AA10: 0 | AB10: 2 | AC10: -1 | AD10: 3 | AE10: 4 | AF10: 1 | AG10: 9 | AH10: -2 | AI10: 6 | AJ10: 13 | AK10: -2 | AL10: 19 | AM10: 16 | AN10: 16 | AO10: 11 | AP10: 8 | AQ10: -2 | AR10: 17 | AS10: -4 | AT10: 8 | AU10: -3 | AV10: -6 | AW10: 12 | AX10: 1 | AY10: 2 | AZ10: 9 | BA10: 21 | BB10: 10 | BC10: 30 | BD10: 17 | BE10: 16 | BF10: 7 | BG10: 20 | BH10: 10 | BI10: 16 | BJ10: 12 | BK10: 9 | BL10: 2 | BM10: -4 | BN10: 8 | BO10: 12 | BP10: 22 | BQ10: 2
B11: =AVERAGE(D11:BA11) -> 3.02 | C11: 409.50491 | D11: 0 | E11: -4 | F11: 22 | G11: 4 | H11: -3 | I11: 8 | J11: 8 | K11: 3 | L11: -1 | M11: 6 | N11: -15 | O11: -4 | P11: -1 | Q11: 0 | R11: 11 | S11: -4 | T11: 5 | U11: 19 | V11: 6 | W11: -10 | X11: 1 | Y11: 6 | Z11: 4 | AA11: -2 | AB11: 10 | AC11: 1 | AD11: 5 | AE11: 6 | AF11: -1 | AG11: -4 | AH11: -32 | AI11: -4 | AJ11: 5 | AK11: 1 | AL11: 2 | AM11: 14 | AN11: 26 | AO11: 8 | AP11: 17 | AQ11: -8 | AR11: 5 | AS11: 4 | AT11: -2 | AU11: -2 | AV11: 16 | AW11: 0 | AX11: -14 | AY11: 1 | AZ11: 19 | BA11: 19 | BB11: 2 | BC11: 8 | BD11: -9 | BE11: 4 | BF11: 1 | BG11: 9 | BH11: 0 | BI11: 0 | BJ11: 1 | BK11: 19 | BL11: 4 | BM11: 12 | BN11: -3 | BO11: 0 | BP11: 6 | BQ11: 6
B12: =AVERAGE(D12:BA12) -> 7.06 | C12: 410.70471 | D12: 13 | E12: 3 | F12: 4 | G12: 20 | H12: 1 | I12: 21 | J12: 10 | K12: 5 | L12: 6 | M12: -5 | N12: 26 | O12: 4 | P12: 10 | Q12: 4 | R12: 3 | S12: -4 | T12: 20 | U12: 8 | V12: 21 | W12: 14 | X12: -9 | Y12: -1 | Z12: -4 | AA12: 1 | AB12: 2 | AC12: 2 | AD12: 2 | AE12: 28 | AF12: 0 | AG12: 7 | AH12: -6 | AI12: -1 | AJ12: 8 | AK12: 9 | AL12: 8 | AM12: 13 | AN12: 23 | AO12: -6 | AP12: 15 | AQ12: 4 | AR12: 7 | AS12: -9 | AT12: 20 | AU12: 7 | AV12: 11 | AW12: 1 | AX12: 6 | AY12: 14 | AZ12: 8 | BA12: 9 | BB12: -1 | BC12: 14 | BD12: 12 | BE12: 5 | BF12: 6 | BG12: 5 | BH12: -13 | BI12: 13 | BJ12: 7 | BK12: -1 | BL12: 7 | BM12: -2 | BN12: 1 | BO12: 28 | BP12: 8 | BQ12: 23
B13: =AVERAGE(D13:BA13) -> 7.28 | C13: 411.90491 | D13: -1 | E13: -1 | F13: 23 | G13: 13 | H13: 4 | I13: 6 | J13: 7 | K13: 6 | L13: -8 | M13: 3 | N13: 16 | O13: -1 | P13: 12 | Q13: -4 | R13: -6 | S13: 1 | T13: 3 | U13: 0 | V13: 0 | W13: 2 | X13: 15 | Y13: 9 | Z13: 6 | AA13: 18 | AB13: 19 | AC13: 3 | AD13: -3 | AE13: 31 | AF13: 11 | AG13: -3 | AH13: 5 | AI13: 14 | AJ13: 9 | AK13: 3 | AL13: 20 | AM13: 16 | AN13: 22 | AO13: 10 | AP13: 11 | AQ13: 0 | AR13: 14 | AS13: -13 | AT13: 8 | AU13: 16 | AV13: 10 | AW13: -5 | AX13: 17 | AY13: 18 | AZ13: -3 | BA13: 11 | BB13: 6 | BC13: 9 | BD13: 12 | BE13: 2 | BF13: 15 | BG13: 13 | BH13: 23 | BI13: -6 | BJ13: 12 | BK13: -6 | BL13: 12 | BM13: 13 | BN13: 12 | BO13: 10 | BP13: 8 | BQ13: -22
B14: =AVERAGE(D14:BA14) -> 6.56 | C14: 413.10559 | D14: 17 | E14: -1 | F14: 1 | G14: 18 | H14: 6 | I14: -1 | J14: 19 | K14: 18 | L14: 8 | M14: 4 | N14: 13 | O14: 9 | P14: 12 | Q14: 1 | R14: -6 | S14: 16 | T14: 20 | U14: 8 | V14: 7 | W14: 3 | X14: 13 | Y14: 9 | Z14: -2 | AA14: 0 | AB14: -6 | AC14: -2 | AD14: 2 | AE14: 0 | AF14: 7 | AG14: -6 | AH14: 13 | AI14: 23 | AJ14: 6 | AK14: -4 | AL14: 10 | AM14: 24 | AN14: 5 | AO14: 9 | AP14: -3 | AQ14: -1 | AR14: 1 | AS14: -10 | AT14: 12 | AU14: 14 | AV14: 0 | AW14: 1 | AX14: 5 | AY14: 12 | AZ14: 16 | BA14: 8 | BB14: 8 | BC14: 10 | BD14: 2 | BE14: 12 | BF14: 9 | BG14: 21 | BH14: 11 | BI14: 8 | BJ14: 20 | BK14: -3 | BL14: 13 | BM14: 0 | BN14: -5 | BO14: 7 | BP14: 6 | BQ14: 9
... B463: =AVERAGE(D463:BA463) -> 13.72 | C463: 999.65863 | D463: 7 | E463: 14 | F463: 36 | G463: 0 | H463: 30 | I463: -2 | J463: 4 | K463: 19 | L463: -5 | M463: -6 | N463: 11 | O463: 3 | P463: 15 | Q463: 4 | R463: 7 | S463: 6 | T463: 34 | U463: 8 | V463: 12 | W463: 11 | X463: 9 | Y463: 9 | Z463: 25 | AA463: 21 | AB463: 26 | AC463: 9 | AD463: 1 | AE463: 24 | AF463: 45 | AG463: -1 | AH463: 0 | AI463: 9 | AJ463: 33 | AK463: 10 | AL463: 19 | AM463: 38 | AN463: 26 | AO463: 25 | AP463: 16 | AQ463: -2 | AR463: 7 | AS463: 10 | AT463: 3 | AU463: 5 | AV463: 19 | AW463: 3 | AX463: -2 | AY463: 16 | AZ463: 37 | BA463: 38 | BB463: 10 | BC463: -14 | BD463: 7 | BE463: 17 | BF463: 10 | BG463: 35 | BH463: 39 | BI463: 46 | BJ463: 53 | BK463: 41 | BL463: 49 | BM463: 31 | BN463: 8 | BO463: 0 | BP463: 9 | BQ463: 16

Sheet 25 percent stain
C1: maximum intensity (a.u.) | D1: =MAX(D3:D463) -> 2817.08
D2: Average intensity of 50 pixels for each wavelength (a.u.) | E2: Wavelength (nm) | F2: Raw spectra data from points on the image. All points are taken from PS
D3: =AVERAGE(F3:BC3) -> 14 | E3: 399.9241 | F3: 10 | G3: 8 | H3: -4 | I3: 30 | J3: 30 | K3: 34 | L3: 49 | M3: 41 | N3: 67 | O3: -12 | P3: 13 | Q3: 13 | R3: 0 | S3: 24 | T3: 13 | U3: 17 | V3: 11 | W3: -5 | X3: 11 | Y3: -10 | Z3: 7 | AA3: 22 | AB3: 53 | AC3: 50 | AD3: -7 | AE3: 9 | AF3: 10 | AG3: 12 | AH3: 0 | AI3: 4 | AJ3: 1 | AK3: 11 | AL3: 15 | AM3: 6 | AN3: 9 | AO3: 16 | AP3: 16 | AQ3: 11 | AR3: 23 | AS3: 4 | AT3: -4 | AU3: 23 | AV3: -3 | AW3: 12 | AX3: 1 | AY3: 9 | AZ3: 6 | BA3: 12 | BB3: 28 | BC3: 4 | BD3: 10 | BE3: 11 | BF3: -2 | BG3: 6 | BH3: 15 | BI3: 6 | BJ3: 11 | BK3: 28 | BL3: 0 | BM3: 11 | BN3: 13 | BO3: -9 | BP3: 18 | BQ3: 1 | BR3: -1 | BS3: -2 | BT3: -3 | BU3: 11 | BV3: 6 | BW3: -1 | BX3: -3 | BY3: 7 | BZ3: -8 | CA3: -5 | CB3: 16 | CC3: 4 | CD3: -8
D4: =AVERAGE(F4:BC4) -> 15.5 | E4: 401.12 | F4: 3 | G4: 3 | H4: 3 | I4: 36 | J4: 41 | K4: 56 | L4: 30 | M4: 51 | N4: 76 | O4: 25 | P4: 11 | Q4: 11 | R4: 9 | S4: 7 | T4: 21 | U4: 25 | V4: 16 | W4: 5 | X4: 5 | Y4: 8 | Z4: 9 | AA4: 8 | AB4: 42 | AC4: 41 | AD4: 16 | AE4: 13 | AF4: 9 | AG4: 12 | AH4: 0 | AI4: 4 | AJ4: 1 | AK4: 19 | AL4: 13 | AM4: 2 | AN4: 29 | AO4: 5 | AP4: 6 | AQ4: 9 | AR4: 7 | AS4: 1 | AT4: 16 | AU4: 20 | AV4: 18 | AW4: 4 | AX4: 13 | AY4: -4 | AZ4: 4 | BA4: 9 | BB4: -11 | BC4: 18 | BD4: -4 | BE4: -17 | BF4: -16 | BG4: 10 | BH4: 11 | BI4: 6 | BJ4: -4 | BK4: 9 | BL4: 0 | BM4: 12 | BN4: 9 | BO4: -5 | BP4: 10 | BQ4: -10 | BR4: 8 | BS4: 0 | BT4: 10 | BU4: 19 | BV4: 13 | BW4: 15 | BX4: 26 | BY4: -14 | BZ4: 0 | CA4: 3 | CB4: 15 | CC4: 1 | CD4: 11
D5: =AVERAGE(F5:BC5) -> 16.44 | E5: 402.3164 | F5: -2 | G5: -2 | H5: -10 | I5: 40 | J5: 55 | K5: 56 | L5: 34 | M5: 36 | N5: 68 | O5: 9 | P5: 9 | Q5: 17 | R5: -3 | S5: 24 | T5: 23 | U5: 28 | V5: 14 | W5: -3 | X5: 23 | Y5: 8 | Z5: 1 | AA5: 12 | AB5: 36 | AC5: 38 | AD5: 41 | AE5: 18 | AF5: 25 | AG5: 6 | AH5: 14 | AI5: 15 | AJ5: -2 | AK5: 22 | AL5: 9 | AM5: 13 | AN5: 10 | AO5: 8 | AP5: 11 | AQ5: 8 | AR5: 14 | AS5: 7 | AT5: 13 | AU5: 15 | AV5: 4 | AW5: 15 | AX5: 17 | AY5: -11 | AZ5: 25 | BA5: 13 | BB5: 7 | BC5: -6 | BD5: 24 | BE5: 17 | BF5: -4 | BG5: 3 | BH5: 15 | BI5: 13 | BJ5: 26 | BK5: 11 | BL5: -9 | BM5: 17 | BN5: -10 | BO5: 14 | BP5: -10 | BQ5: -7 | BR5: 5 | BS5: 15 | BT5: 7 | BU5: -1 | BV5: 5 | BW5: 17 | BX5: 8 | BY5: 3 | BZ5: -31 | CA5: -2 | CB5: -5 | CC5: 3 | CD5: -8
D6: =AVERAGE(F6:BC6) -> 15.14 | E6: 403.5133 | F6: -8 | G6: 5 | H6: 6 | I6: 43 | J6: 36 | K6: 37 | L6: 32 | M6: 37 | N6: 46 | O6: 7 | P6: 5 | Q6: 11 | R6: 0 | S6: 32 | T6: 33 | U6: 4 | V6: -5 | W6: 12 | X6: 19 | Y6: 10 | Z6: 1 | AA6: 26 | AB6: 40 | AC6: 49 | AD6: 14 | AE6: 11 | AF6: -7 | AG6: 14 | AH6: -2 | AI6: 8 | AJ6: 31 | AK6: 19 | AL6: 28 | AM6: 28 | AN6: 9 | AO6: 18 | AP6: 1 | AQ6: 6 | AR6: 7 | AS6: 3 | AT6: 9 | AU6: 32 | AV6: 5 | AW6: 9 | AX6: -1 | AY6: 5 | AZ6: 3 | BA6: 10 | BB6: 14 | BC6: 5 | BD6: 9 | BE6: 0 | BF6: -3 | BG6: -3 | BH6: 3 | BI6: 15 | BJ6: 12 | BK6: 30 | BL6: 5 | BM6: 18 | BN6: 5 | BO6: 18 | BP6: -1 | BQ6: -2 | BR6: 10 | BS6: -1 | BT6: 7 | BU6: -5 | BV6: -5 | BW6: 9 | BX6: 6 | BY6: -11 | BZ6: 2 | CA6: 12 | CB6: -1 | CC6: 6 | CD6: 7
D7: =AVERAGE(F7:BC7) -> 17.16 | E7: 404.7106 | F7: -7 | G7: 9 | H7: 2 | I7: 48 | J7: 28 | K7: 46 | L7: 62 | M7: 50 | N7: 79 | O7: 7 | P7: 21 | Q7: 1 | R7: 29 | S7: 1 | T7: 29 | U7: 36 | V7: 12 | W7: 4 | X7: 7 | Y7: 8 | Z7: 26 | AA7: 18 | AB7: 53 | AC7: 23 | AD7: 21 | AE7: 14 | AF7: 12 | AG7: 7 | AH7: 20 | AI7: 4 | AJ7: -2 | AK7: 23 | AL7: 32 | AM7: 7 | AN7: 3 | AO7: 10 | AP7: -7 | AQ7: 9 | AR7: 5 | AS7: -6 | AT7: 12 | AU7: 6 | AV7: 1 | AW7: 29 | AX7: 19 | AY7: 9 | AZ7: 15 | BA7: 17 | BB7: -11 | BC7: 17 | BD7: 5 | BE7: 4 | BF7: 1 | BG7: 8 | BH7: 3 | BI7: 17 | BJ7: 16 | BK7: 30 | BL7: 10 | BM7: -3 | BN7: 11 | BO7: 0 | BP7: -7 | BQ7: 8 | BR7: -1 | BS7: 1 | BT7: 3 | BU7: 0 | BV7: -11 | BW7: 5 | BX7: 25 | BY7: 7 | BZ7: 5 | CA7: -2 | CB7: 0 | CC7: 3 | CD7: 13
D8: =AVERAGE(F8:BC8) -> 17.6 | E8: 405.9085 | F8: 20 | G8: -1 | H8: -4 | I8: 36 | J8: 55 | K8: 79 | L8: 58 | M8: 46 | N8: 54 | O8: 19 | P8: 18 | Q8: -6 | R8: 5 | S8: 13 | T8: 26 | U8: 27 | V8: 17 | W8: 2 | X8: 9 | Y8: 10 | Z8: 21 | AA8: 7 | AB8: 70 | AC8: 37 | AD8: 19 | AE8: 9 | AF8: 15 | AG8: -2 | AH8: 8 | AI8: 23 | AJ8: 17 | AK8: -5 | AL8: 25 | AM8: 14 | AN8: 3 | AO8: 6 | AP8: -1 | AQ8: 17 | AR8: 6 | AS8: 15 | AT8: 13 | AU8: 8 | AV8: 7 | AW8: 19 | AX8: 15 | AY8: 10 | AZ8: 11 | BA8: 7 | BB8: 4 | BC8: -1 | BD8: 17 | BE8: 12 | BF8: -7 | BG8: 0 | BH8: 19 | BI8: 1 | BJ8: 13 | BK8: 16 | BL8: 1 | BM8: 5 | BN8: 3 | BO8: -2 | BP8: -11 | BQ8: 5 | BR8: -3 | BS8: 12 | BT8: -1 | BU8: 4 | BV8: 17 | BW8: 0 | BX8: 9 | BY8: -18 | BZ8: 3 | CA8: -6 | CB8: 3 | CC8: 11 | CD8: 3
D9: =AVERAGE(F9:BC9) -> 18.72 | E9: 407.1068 | F9: 9 | G9: 8 | H9: 14 | I9: 40 | J9: 46 | K9: 58 | L9: 50 | M9: 38 | N9: 83 | O9: 6 | P9: 22 | Q9: 0 | R9: 4 | S9: 14 | T9: 35 | U9: 35 | V9: 10 | W9: 4 | X9: 1 | Y9: 19 | Z9: 17 | AA9: 34 | AB9: 50 | AC9: 40 | AD9: 37 | AE9: 24 | AF9: 2 | AG9: 4 | AH9: 24 | AI9: 10 | AJ9: 8 | AK9: -1 | AL9: 25 | AM9: -2 | AN9: 16 | AO9: -2 | AP9: 3 | AQ9: 22 | AR9: 23 | AS9: 15 | AT9: 3 | AU9: 19 | AV9: 11 | AW9: 11 | AX9: 17 | AY9: 18 | AZ9: 10 | BA9: 10 | BB9: 0 | BC9: -8 | BD9: -16 | BE9: -2 | BF9: -4 | BG9: 10 | BH9: -1 | BI9: 2 | BJ9: -6 | BK9: 17 | BL9: 21 | BM9: 7 | BN9: 7 | BO9: 12 | BP9: 13 | BQ9: 19 | BR9: -3 | BS9: 1 | BT9: 11 | BU9: 4 | BV9: 16 | BW9: -3 | BX9: -4 | BY9: -3 | BZ9: 16 | CA9: -16 | CB9: 3 | CC9: -1 | CD9: 2
D10: =AVERAGE(F10:BC10) -> 19.38 | E10: 408.3056 | F10: 25 | G10: 3 | H10: -10 | I10: 37 | J10: 64 | K10: 83 | L10: 69 | M10: 66 | N10: 92 | O10: 4 | P10: -13 | Q10: 5 | R10: 7 | S10: 25 | T10: 24 | U10: 8 | V10: 16 | W10: 11 | X10: 16 | Y10: -7 | Z10: -9 | AA10: 25 | AB10: 64 | AC10: 46 | AD10: 0 | AE10: 13 | AF10: 7 | AG10: 14 | AH10: 23 | AI10: 6 | AJ10: 18 | AK10: 9 | AL10: 20 | AM10: 26 | AN10: 24 | AO10: -2 | AP10: 5 | AQ10: 6 | AR10: 3 | AS10: 1 | AT10: -1 | AU10: 27 | AV10: 31 | AW10: 32 | AX10: 17 | AY10: 28 | AZ10: -3 | BA10: 12 | BB10: 7 | BC10: -5 | BD10: -1 | BE10: 0 | BF10: 12 | BG10: 14 | BH10: 12 | BI10: 11 | BJ10: 10 | BK10: 6 | BL10: 2 | BM10: 3 | BN10: 6 | BO10: -1 | BP10: 8 | BQ10: 7 | BR10: 3 | BS10: 12 | BT10: 14 | BU10: 1 | BV10: 6 | BW10: 11 | BX10: -4 | BY10: -2 | BZ10: 15 | CA10: 10 | CB10: 11 | CC10: 4 | CD10: 7
D11: =AVERAGE(F11:BC11) -> 19.04 | E11: 409.5049 | F11: -7 | G11: -12 | H11: -4 | I11: 58 | J11: 39 | K11: 73 | L11: 66 | M11: 70 | N11: 90 | O11: 13 | P11: 10 | Q11: 13 | R11: -4 | S11: 15 | T11: 7 | U11: 33 | V11: 32 | W11: 3 | X11: -12 | Y11: 0 | Z11: 19 | AA11: 7 | AB11: 68 | AC11: 51 | AD11: 21 | AE11: 30 | AF11: 9 | AG11: 22 | AH11: 20 | AI11: -8 | AJ11: -4 | AK11: 3 | AL11: 18 | AM11: 22 | AN11: 13 | AO11: 15 | AP11: 23 | AQ11: -3 | AR11: 8 | AS11: -6 | AT11: 2 | AU11: 8 | AV11: 14 | AW11: 29 | AX11: 18 | AY11: 13 | AZ11: 19 | BA11: 22 | BB11: 8 | BC11: 8 | BD11: 2 | BE11: 13 | BF11: 9 | BG11: 4 | BH11: 9 | BI11: 12 | BJ11: 10 | BK11: 24 | BL11: 0 | BM11: 18 | BN11: 13 | BO11: 1 | BP11: 14 | BQ11: -1 | BR11: -10 | BS11: 20 | BT11: 2 | BU11: 11 | BV11: 6 | BW11: 10 | BX11: 1 | BY11: -3 | BZ11: -1 | CA11: 11 | CB11: 21 | CC11: 3 | CD11: 25
D12: =AVERAGE(F12:BC12) -> 22.26 | E12: 410.7047 | F12: -12 | G12: 2 | H12: 0 | I12: 54 | J12: 81 | K12: 89 | L12: 75 | M12: 89 | N12: 82 | O12: -7 | P12: 7 | Q12: 8 | R12: 0 | S12: 21 | T12: 20 | U12: 40 | V12: 7 | W12: 21 | X12: 20 | Y12: 2 | Z12: 26 | AA12: 25 | AB12: 49 | AC12: 40 | AD12: 22 | AE12: 18 | AF12: -14 | AG12: 5 | AH12: 25 | AI12: 10 | AJ12: 15 | AK12: 12 | AL12: 25 | AM12: 40 | AN12: 13 | AO12: 14 | AP12: 12 | AQ12: 20 | AR12: -6 | AS12: 16 | AT12: 31 | AU12: 18 | AV12: 22 | AW12: 0 | AX12: 5 | AY12: 16 | AZ12: 26 | BA12: 20 | BB12: -4 | BC12: 13 | BD12: 11 | BE12: 10 | BF12: -3 | BG12: 11 | BH12: 9 | BI12: 8 | BJ12: -4 | BK12: 26 | BL12: 8 | BM12: 3 | BN12: 2 | BO12: 9 | BP12: 3 | BQ12: 10 | BR12: -7 | BS12: 6 | BT12: 10 | BU12: 22 | BV12: 15 | BW12: 15 | BX12: 11 | BY12: 7 | BZ12: 4 | CA12: 12 | CB12: 1 | CC12: 5 | CD12: 9
D13: =AVERAGE(F13:BC13) -> 22.9 | E13: 411.9049 | F13: 17 | G13: -11 | H13: 3 | I13: 60 | J13: 72 | K13: 93 | L13: 79 | M13: 74 | N13: 89 | O13: -6 | P13: 11 | Q13: 14 | R13: 13 | S13: 20 | T13: 25 | U13: 27 | V13: 16 | W13: 33 | X13: -7 | Y13: 7 | Z13: 26 | AA13: 36 | AB13: 71 | AC13: 63 | AD13: 39 | AE13: 28 | AF13: -4 | AG13: 13 | AH13: 3 | AI13: 5 | AJ13: 15 | AK13: 5 | AL13: 17 | AM13: 31 | AN13: 11 | AO13: -4 | AP13: 18 | AQ13: 7 | AR13: 6 | AS13: 6 | AT13: 0 | AU13: 5 | AV13: 19 | AW13: 18 | AX13: 18 | AY13: 23 | AZ13: 16 | BA13: 9 | BB13: -1 | BC13: 17 | BD13: -14 | BE13: 8 | BF13: -4 | BG13: -1 | BH13: 1 | BI13: 1 | BJ13: 9 | BK13: 25 | BL13: 19 | BM13: 25 | BN13: 19 | BO13: 2 | BP13: 14 | BQ13: 6 | BR13: -3 | BS13: 12 | BT13: 4 | BU13: 6 | BV13: 17 | BW13: 19 | BX13: 19 | BY13: 24 | BZ13: 6 | CA13: 12 | CB13: 1 | CC13: -9 | CD13: 4
D14: =AVERAGE(F14:BC14) -> 22.18 | E14: 413.1056 | F14: 9 | G14: -11 | H14: 0 | I14: 59 | J14: 76 | K14: 108 | L14: 52 | M14: 65 | N14: 105 | O14: 32 | P14: 8 | Q14: 20 | R14: -3 | S14: 16 | T14: 48 | U14: 47 | V14: 27 | W14: 5 | X14: 1 | Y14: -3 | Z14: 7 | AA14: 33 | AB14: 44 | AC14: 56 | AD14: 15 | AE14: 19 | AF14: 1 | AG14: 9 | AH14: 9 | AI14: 7 | AJ14: 24 | AK14: 17 | AL14: 17 | AM14: 27 | AN14: 16 | AO14: 28 | AP14: 14 | AQ14: 25 | AR14: 6 | AS14: 11 | AT14: -2 | AU14: 10 | AV14: 3 | AW14: 6 | AX14: 15 | AY14: 17 | AZ14: 11 | BA14: 5 | BB14: -4 | BC14: 2 | BD14: 0 | BE14: -2 | BF14: 3 | BG14: -2 | BH14: 11 | BI14: -2 | BJ14: 7 | BK14: 29 | BL14: 27 | BM14: 1 | BN14: 5 | BO14: 0 | BP14: 21 | BQ14: 16 | BR14: 14 | BS14: 8 | BT14: -4 | BU14: 33 | BV14: -3 | BW14: -3 | BX14: 14 | BY14: 14 | BZ14: 2 | CA14: 10 | CB14: -3 | CC14: 15 | CD14: -6
... D463: =AVERAGE(F463:BC463) -> 30.18 | E463: 999.6586 | F463: -10 | G463: 5 | H463: -3 | I463: 40 | J463: 48 | K463: 82 | L463: 60 | M463: 57 | N463: 84 | O463: 18 | P463: 11 | Q463: 5 | R463: -1 | S463: 64 | T463: 61 | U463: 64 | V463: 25 | W463: 19 | X463: 41 | Y463: 30 | Z463: 41 | AA463: 50 | AB463: 122 | AC463: 98 | AD463: 20 | AE463: 26 | AF463: 12 | AG463: 4 | AH463: 5 | AI463: 15 | AJ463: 20 | AK463: 27 | AL463: 26 | AM463: 38 | AN463: 0 | AO463: 14 | AP463: 17 | AQ463: 25 | AR463: 17 | AS463: 8 | AT463: 20 | AU463: 71 | AV463: 13 | AW463: 27 | AX463: 27 | AY463: 25 | AZ463: 41 | BA463: 4 | BB463: 10 | BC463: -14 | BD463: 4 | BE463: -9 | BF463: 16 | BG463: 9 | BH463: -4 | BI463: 8 | BJ463: 1 | BK463: 31 | BL463: 85 | BM463: 72 | BN463: 14 | BO463: 18 | BP463: 6 | BQ463: 19 | BR463: 17 | BS463: 8 | BT463: 14 | BU463: -7 | BV463: 29 | BW463: 32 | BX463: 11 | BY463: 22 | BZ463: 23 | CA463: 0 | CB463: 10 | CC463: 19 | CD463: 6

Sheet 50 percent stain
C1: Peak Wavelenghts (nm) | D1: =(VLOOKUP(D2,D4:E464,2,FALSE)) -> 683.71039
C2: maximum intensity (a.u.) | D2: =MAX(D4:D464) -> 4711.14
D3: Average intensity of 50 pixels for each wavelength (a.u.) | E3: Wavelength (nm) | F3: Raw spectra data from points on the image. All points are taken from PS
D4: =AVERAGE(F4:BC4) -> 7.78 | E4: 399.9241 | F4: 21 | G4: 4 | H4: 3 | I4: 5 | J4: 20 | K4: 9 | L4: 9 | M4: 2 | N4: -8 | O4: -1 | P4: 2 | Q4: 2 | R4: 11 | S4: 17 | T4: 2 | U4: 20 | V4: 12 | W4: -5 | X4: 11 | Y4: 29 | Z4: 6 | AA4: 12 | AB4: 3 | AC4: 15 | AD4: -3 | AE4: 29 | AF4: 5 | AG4: -8 | AH4: -3 | AI4: 3 | AJ4: 7 | AK4: 7 | AL4: 25 | AM4: -2 | AN4: 7 | AO4: 10 | AP4: 6 | AQ4: 21 | AR4: 9 | AS4: 5 | AT4: 10 | AU4: 8 | AV4: 14 | AW4: -1 | AX4: 18 | AY4: -4 | AZ4: -9 | BA4: 18 | BB4: 10 | BC4: 6 | BD4: -1 | BE4: 4 | BF4: -2 | BG4: 2 | BH4: 4 | BI4: 14 | BJ4: 10 | BK4: -1 | BL4: 0 | BM4: 11 | BN4: 13 | BO4: -9 | BP4: 18 | BQ4: 1 | BR4: -1 | BS4: -2 | BT4: -3 | BU4: 11 | BV4: 6 | BW4: -1 | BX4: -3 | BY4: 7 | BZ4: -8 | CA4: -5 | CB4: 16 | CC4: 4 | CD4: -8
D5: =AVERAGE(F5:BC5) -> 5.6 | E5: 401.12 | F5: 11 | G5: 5 | H5: 31 | I5: 9 | J5: 25 | K5: -1 | L5: -17 | M5: 3 | N5: -14 | O5: 5 | P5: 2 | Q5: -8 | R5: 11 | S5: 2 | T5: -5 | U5: 12 | V5: 30 | W5: -21 | X5: 7 | Y5: 2 | Z5: 13 | AA5: 6 | AB5: 18 | AC5: 15 | AD5: 33 | AE5: 11 | AF5: 14 | AG5: 11 | AH5: 17 | AI5: 11 | AJ5: 1 | AK5: 2 | AL5: 4 | AM5: 16 | AN5: 15 | AO5: 14 | AP5: -7 | AQ5: -7 | AR5: -15 | AS5: 0 | AT5: 13 | AU5: -19 | AV5: -2 | AW5: -5 | AX5: 7 | AY5: 2 | AZ5: 0 | BA5: 4 | BB5: 5 | BC5: 14 | BD5: -3 | BE5: 30 | BF5: -8 | BG5: 15 | BH5: 8 | BI5: -2 | BJ5: 4 | BK5: 1 | BL5: 0 | BM5: 12 | BN5: 9 | BO5: -5 | BP5: 10 | BQ5: -10 | BR5: 8 | BS5: 0 | BT5: 10 | BU5: 19 | BV5: 13 | BW5: 15 | BX5: 26 | BY5: -14 | BZ5: 0 | CA5: 3 | CB5: 15 | CC5: 1 | CD5: 11
D6: =AVERAGE(F6:BC6) -> 6.54 | E6: 402.31641 | F6: -2 | G6: 36 | H6: 32 | I6: -8 | J6: 6 | K6: -2 | L6: -3 | M6: 3 | N6: 0 | O6: 12 | P6: -3 | Q6: -5 | R6: -16 | S6: 4 | T6: 21 | U6: 14 | V6: 18 | W6: -3 | X6: 21 | Y6: 15 | Z6: 4 | AA6: 5 | AB6: 14 | AC6: 18 | AD6: 17 | AE6: 3 | AF6: 5 | AG6: -8 | AH6: 10 | AI6: -1 | AJ6: -2 | AK6: 11 | AL6: 5 | AM6: -3 | AN6: 1 | AO6: 7 | AP6: 3 | AQ6: 11 | AR6: 9 | AS6: -5 | AT6: 8 | AU6: 10 | AV6: -8 | AW6: 1 | AX6: 13 | AY6: 10 | AZ6: 10 | BA6: 8 | BB6: 12 | BC6: 19 | BD6: 16 | BE6: 14 | BF6: 19 | BG6: 8 | BH6: 9 | BI6: 2 | BJ6: 27 | BK6: 22 | BL6: -9 | BM6: 17 | BN6: -10 | BO6: 14 | BP6: -10 | BQ6: -7 | BR6: 5 | BS6: 15 | BT6: 7 | BU6: -1 | BV6: 5 | BW6: 17 | BX6: 8 | BY6: 3 | BZ6: -31 | CA6: -2 | CB6: -5 | CC6: 3 | CD6: -8
D7: =AVERAGE(F7:BC7) -> 7.68 | E7: 403.51331 | F7: 3 | G7: 20 | H7: 28 | I7: 7 | J7: 12 | K7: 29 | L7: 10 | M7: 3 | N7: 2 | O7: 19 | P7: -5 | Q7: -8 | R7: 7 | S7: 8 | T7: 5 | U7: -13 | V7: 10 | W7: 14 | X7: 15 | Y7: 16 | Z7: 29 | AA7: 12 | AB7: 12 | AC7: 4 | AD7: 17 | AE7: 7 | AF7: 8 | AG7: 5 | AH7: 9 | AI7: -4 | AJ7: -2 | AK7: -5 | AL7: -9 | AM7: 13 | AN7: -2 | AO7: -6 | AP7: 8 | AQ7: 4 | AR7: 6 | AS7: 19 | AT7: 2 | AU7: -2 | AV7: 3 | AW7: 11 | AX7: 2 | AY7: 6 | AZ7: 10 | BA7: 10 | BB7: 12 | BC7: 23 | BD7: 10 | BE7: 14 | BF7: 1 | BG7: 12 | BH7: 5 | BI7: 10 | BJ7: 24 | BK7: 16 | BL7: 5 | BM7: 18 | BN7: 5 | BO7: 18 | BP7: -1 | BQ7: -2 | BR7: 10 | BS7: -1 | BT7: 7 | BU7: -5 | BV7: -5 | BW7: 9 | BX7: 6 | BY7: -11 | BZ7: 2 | CA7: 12 | CB7: -1 | CC7: 6 | CD7: 7
D8: =AVERAGE(F8:BC8) -> 10.44 | E8: 404.7106 | F8: -3 | G8: 32 | H8: 33 | I8: -3 | J8: 7 | K8: 19 | L8: 18 | M8: 4 | N8: 7 | O8: 2 | P8: 14 | Q8: -4 | R8: 14 | S8: 7 | T8: -13 | U8: 13 | V8: -8 | W8: 15 | X8: 1 | Y8: 17 | Z8: 13 | AA8: 5 | AB8: 22 | AC8: 13 | AD8: 21 | AE8: 11 | AF8: 1 | AG8: 19 | AH8: -4 | AI8: 6 | AJ8: 15 | AK8: 14 | AL8: 15 | AM8: 14 | AN8: 10 | AO8: 12 | AP8: 20 | AQ8: -1 | AR8: -9 | AS8: 22 | AT8: 0 | AU8: -4 | AV8: 8 | AW8: 23 | AX8: 28 | AY8: 10 | AZ8: 26 | BA8: 4 | BB8: 20 | BC8: 16 | BD8: 2 | BE8: 7 | BF8: 14 | BG8: 14 | BH8: 26 | BI8: 8 | BJ8: -14 | BK8: 39 | BL8: 10 | BM8: -3 | BN8: 11 | BO8: 0 | BP8: -7 | BQ8: 8 | BR8: -1 | BS8: 1 | BT8: 3 | BU8: 0 | BV8: -11 | BW8: 5 | BX8: 25 | BY8: 7 | BZ8: 5 | CA8: -2 | CB8: 0 | CC8: 3 | CD8: 13
D9: =AVERAGE(F9:BC9) -> 9.54 | E9: 405.90851 | F9: 4 | G9: 10 | H9: 23 | I9: 16 | J9: 20 | K9: 32 | L9: 23 | M9: -3 | N9: 7 | O9: -7 | P9: 8 | Q9: 5 | R9: 19 | S9: 8 | T9: 4 | U9: 3 | V9: -1 | W9: 2 | X9: 11 | Y9: 13 | Z9: 11 | AA9: -1 | AB9: 21 | AC9: 22 | AD9: 9 | AE9: 5 | AF9: 13 | AG9: 2 | AH9: 10 | AI9: 2 | AJ9: 11 | AK9: 9 | AL9: 2 | AM9: 3 | AN9: 3 | AO9: 7 | AP9: 21 | AQ9: 20 | AR9: -4 | AS9: 10 | AT9: 16 | AU9: -5 | AV9: -4 | AW9: 19 | AX9: 17 | AY9: 6 | AZ9: 0 | BA9: 25 | BB9: 3 | BC9: 27 | BD9: 32 | BE9: -5 | BF9: 18 | BG9: 10 | BH9: 20 | BI9: 4 | BJ9: 20 | BK9: 15 | BL9: 1 | BM9: 5 | BN9: 3 | BO9: -2 | BP9: -11 | BQ9: 5 | BR9: -3 | BS9: 12 | BT9: -1 | BU9: 4 | BV9: 17 | BW9: 0 | BX9: 9 | BY9: -18 | BZ9: 3 | CA9: -6 | CB9: 3 | CC9: 11 | CD9: 3
D10: =AVERAGE(F10:BC10) -> 11.14 | E10: 407.10681 | F10: 31 | G10: 46 | H10: 15 | I10: 23 | J10: 17 | K10: 22 | L10: 10 | M10: -5 | N10: 10 | O10: 4 | P10: 5 | Q10: -1 | R10: 19 | S10: 13 | T10: -8 | U10: 2 | V10: 11 | W10: 18 | X10: -7 | Y10: 3 | Z10: 10 | AA10: 13 | AB10: 6 | AC10: 14 | AD10: 30 | AE10: 29 | AF10: 16 | AG10: 17 | AH10: -4 | AI10: 4 | AJ10: 10 | AK10: 19 | AL10: 4 | AM10: 14 | AN10: 9 | AO10: 17 | AP10: 18 | AQ10: -4 | AR10: 5 | AS10: 8 | AT10: 21 | AU10: 1 | AV10: -17 | AW10: 15 | AX10: 23 | AY10: 12 | AZ10: 3 | BA10: 20 | BB10: 3 | BC10: 13 | BD10: 9 | BE10: 8 | BF10: 23 | BG10: 15 | BH10: 13 | BI10: 10 | BJ10: 12 | BK10: 18 | BL10: 21 | BM10: 7 | BN10: 7 | BO10: 12 | BP10: 13 | BQ10: 19 | BR10: -3 | BS10: 1 | BT10: 11 | BU10: 4 | BV10: 16 | BW10: -3 | BX10: -4 | BY10: -3 | BZ10: 16 | CA10: -16 | CB10: 3 | CC10: -1 | CD10: 2
D11: =AVERAGE(F11:BC11) -> 10.2 | E11: 408.3056 | F11: 22 | G11: 32 | H11: 18 | I11: 22 | J11: 19 | K11: 45 | L11: 12 | M11: -12 | N11: -3 | O11: 6 | P11: 4 | Q11: 5 | R11: 16 | S11: 7 | T11: -4 | U11: 9 | V11: 22 | W11: 14 | X11: 4 | Y11: 11 | Z11: 15 | AA11: 9 | AB11: 8 | AC11: 20 | AD11: 28 | AE11: 15 | AF11: 5 | AG11: 30 | AH11: 13 | AI11: 1 | AJ11: 6 | AK11: 13 | AL11: 5 | AM11: -1 | AN11: 3 | AO11: 12 | AP11: 4 | AQ11: 12 | AR11: 8 | AS11: 1 | AT11: -4 | AU11: 2 | AV11: 4 | AW11: 13 | AX11: 9 | AY11: 8 | AZ11: 18 | BA11: 9 | BB11: -4 | BC11: -1 | BD11: 22 | BE11: 13 | BF11: 3 | BG11: 7 | BH11: 7 | BI11: 30 | BJ11: 13 | BK11: 18 | BL11: 2 | BM11: 3 | BN11: 6 | BO11: -1 | BP11: 8 | BQ11: 7 | BR11: 3 | BS11: 12 | BT11: 14 | BU11: 1 | BV11: 6 | BW11: 11 | BX11: -4 | BY11: -2 | BZ11: 15 | CA11: 10 | CB11: 11 | CC11: 4 | CD11: 7
D12: =AVERAGE(F12:BC12) -> 11.72 | E12: 409.50491 | F12: 27 | G12: 37 | H12: 18 | I12: 16 | J12: 8 | K12: 25 | L12: 15 | M12: 7 | N12: -1 | O12: 3 | P12: 4 | Q12: 12 | R12: 24 | S12: 18 | T12: 4 | U12: 4 | V12: 5 | W12: 9 | X12: -6 | Y12: 0 | Z12: 4 | AA12: 12 | AB12: 12 | AC12: 29 | AD12: 20 | AE12: 36 | AF12: 23 | AG12: 2 | AH12: 10 | AI12: 9 | AJ12: 16 | AK12: 14 | AL12: 13 | AM12: 8 | AN12: 1 | AO12: 12 | AP12: 1 | AQ12: 8 | AR12: 9 | AS12: -7 | AT12: 11 | AU12: 2 | AV12: 12 | AW12: 11 | AX12: 8 | AY12: 16 | AZ12: 16 | BA12: 14 | BB12: 9 | BC12: 26 | BD12: 17 | BE12: 7 | BF12: 2 | BG12: 10 | BH12: 21 | BI12: 21 | BJ12: 21 | BK12: 13 | BL12: 0 | BM12: 18 | BN12: 13 | BO12: 1 | BP12: 14 | BQ12: -1 | BR12: -10 | BS12: 20 | BT12: 2 | BU12: 11 | BV12: 6 | BW12: 10 | BX12: 1 | BY12: -3 | BZ12: -1 | CA12: 11 | CB12: 21 | CC12: 3 | CD12: 25
D13: =AVERAGE(F13:BC13) -> 13.08 | E13: 410.70471 | F13: 19 | G13: 36 | H13: 26 | I13: 29 | J13: 33 | K13: 32 | L13: 6 | M13: 6 | N13: 4 | O13: 6 | P13: 15 | Q13: 0 | R13: 16 | S13: 21 | T13: -12 | U13: 7 | V13: 15 | W13: 22 | X13: -3 | Y13: 11 | Z13: 16 | AA13: 10 | AB13: 15 | AC13: 8 | AD13: 3 | AE13: 28 | AF13: 22 | AG13: 31 | AH13: -4 | AI13: 5 | AJ13: 18 | AK13: -3 | AL13: 7 | AM13: 13 | AN13: 5 | AO13: 3 | AP13: 6 | AQ13: 2 | AR13: 19 | AS13: 17 | AT13: 10 | AU13: 29 | AV13: 22 | AW13: 19 | AX13: 21 | AY13: 11 | AZ13: 7 | BA13: 5 | BB13: 5 | BC13: 15 | BD13: 9 | BE13: 5 | BF13: 8 | BG13: 12 | BH13: 5 | BI13: 15 | BJ13: 0 | BK13: -12 | BL13: 8 | BM13: 3 | BN13: 2 | BO13: 9 | BP13: 3 | BQ13: 10 | BR13: -7 | BS13: 6 | BT13: 10 | BU13: 22 | BV13: 15 | BW13: 15 | BX13: 11 | BY13: 7 | BZ13: 4 | CA13: 12 | CB13: 1 | CC13: 5 | CD13: 9
D14: =AVERAGE(F14:BC14) -> 13.1 | E14: 411.90491 | F14: 13 | G14: 41 | H14: 24 | I14: 23 | J14: 15 | K14: 44 | L14: 26 | M14: -2 | N14: 3 | O14: 5 | P14: 14 | Q14: 6 | R14: 17 | S14: 13 | T14: 16 | U14: -3 | V14: 10 | W14: 8 | X14: -7 | Y14: 19 | Z14: 13 | AA14: 10 | AB14: 24 | AC14: 43 | AD14: 2 | AE14: 26 | AF14: 18 | AG14: 6 | AH14: 12 | AI14: 5 | AJ14: 19 | AK14: 4 | AL14: 9 | AM14: -7 | AN14: 12 | AO14: 8 | AP14: -14 | AQ14: 30 | AR14: 26 | AS14: 0 | AT14: 18 | AU14: 24 | AV14: 30 | AW14: -2 | AX14: 8 | AY14: 4 | AZ14: 19 | BA14: 3 | BB14: 12 | BC14: 8 | BD14: 24 | BE14: 20 | BF14: 17 | BG14: 11 | BH14: 11 | BI14: 8 | BJ14: 14 | BK14: -2 | BL14: 19 | BM14: 25 | BN14: 19 | BO14: 2 | BP14: 14 | BQ14: 6 | BR14: -3 | BS14: 12 | BT14: 4 | BU14: 6 | BV14: 17 | BW14: 19 | BX14: 19 | BY14: 24 | BZ14: 6 | CA14: 12 | CB14: 1 | CC14: -9 | CD14: 4
D15: =AVERAGE(F15:BC15) -> 11.1 | E15: 413.10559 | F15: 18 | G15: 45 | H15: 14 | I15: 9 | J15: 13 | K15: 38 | L15: 2 | M15: 14 | N15: 1 | O15: 2 | P15: -6 | Q15: -2 | R15: 15 | S15: 20 | T15: 2 | U15: 1 | V15: 0 | W15: 8 | X15: 6 | Y15: 10 | Z15: -6 | AA15: 5 | AB15: 38 | AC15: 42 | AD15: 19 | AE15: 27 | AF15: 21 | AG15: -1 | AH15: 19 | AI15: 5 | AJ15: 6 | AK15: 0 | AL15: 4 | AM15: -1 | AN15: 17 | AO15: 21 | AP15: 4 | AQ15: 14 | AR15: 7 | AS15: 5 | AT15: 6 | AU15: 5 | AV15: 8 | AW15: 9 | AX15: 11 | AY15: -3 | AZ15: 15 | BA15: 17 | BB15: 19 | BC15: 12 | BD15: 15 | BE15: 21 | BF15: 21 | BG15: -2 | BH15: 21 | BI15: 22 | BJ15: 5 | BK15: 14 | BL15: 27 | BM15: 1 | BN15: 5 | BO15: 0 | BP15: 21 | BQ15: 16 | BR15: 14 | BS15: 8 | BT15: -4 | BU15: 33 | BV15: -3 | BW15: -3 | BX15: 14 | BY15: 14 | BZ15: 2 | CA15: 10 | CB15: -3 | CC15: 15 | CD15: -6
... D463: =AVERAGE(F463:BC463) -> 108.32 | E463: 999.30463 | F463: 44 | G463: 244 | H463: 192 | I463: 72 | J463: 675 | K463: 356 | L463: 67 | M463: 35 | N463: -9 | O463: 5 | P463: 12 | Q463: 7 | R463: 33 | S463: 19 | T463: 20 | U463: 58 | V463: 59 | W463: 54 | X463: 20 | Y463: 62 | Z463: 73 | AA463: 86 | AB463: 252 | AC463: 311 | AD463: 338 | AE463: 234 | AF463: 151 | AG463: 81 | AH463: 31 | AI463: 70 | AJ463: 35 | AK463: 19 | AL463: 20 | AM463: 34 | AN463: 55 | AO463: 131 | AP463: 68 | AQ463: 33 | AR463: 34 | AS463: 36 | AT463: 54 | AU463: 57 | AV463: 180 | AW463: 258 | AX463: 196 | AY463: 202 | AZ463: 65 | BA463: 70 | BB463: 94 | BC463: 123 | BD463: 132 | BE463: 108 | BF463: 94 | BG463: 103 | BH463: 92 | BI463: 68 | BJ463: 93 | BK463: 89 | BL463: 119 | BM463: 89 | BN463: 9 | BO463: 38 | BP463: 7 | BQ463: 6 | BR463: 18 | BS463: 12 | BT463: 13 | BU463: 23 | BV463: -4 | BW463: 20 | BX463: 3 | BY463: 21 | BZ463: 4 | CA463: 14 | CB463: 29 | CC463: 15 | CD463: 5
D464: =AVERAGE(F464:BC464) -> 101.4 | E464: 999.6586 | F464: 641 | G464: 368 | H464: 45 | I464: 6 | J464: 4 | K464: 7 | L464: 3 | M464: 20 | N464: 22 | O464: 28 | P464: 14 | Q464: 56 | R464: 62 | S464: 36 | T464: 29 | U464: 64 | V464: 78 | W464: 100 | X464: 229 | Y464: 290 | Z464: 325 | AA464: 221 | AB464: 156 | AC464: 86 | AD464: 54 | AE464: 69 | AF464: 20 | AG464: 9 | AH464: 17 | AI464: 16 | AJ464: 61 | AK464: 139 | AL464: 64 | AM464: 38 | AN464: 21 | AO464: 20 | AP464: 36 | AQ464: 52 | AR464: 142 | AS464: 220 | AT464: 204 | AU464: 191 | AV464: 84 | AW464: 103 | AX464: 109 | AY464: 150 | AZ464: 107 | BA464: 111 | BB464: 57 | BC464: 86 | BD464: 70 | BE464: 86 | BF464: 57 | BG464: 58 | BH464: 85 | BI464: 72 | BJ464: 14 | BK464: 18 | BL464: 6 | BM464: 19 | BN464: 17 | BO464: 8 | BP464: 14 | BQ464: -7 | BR464: 29 | BS464: 32 | BT464: 11 | BU464: 22 | BV464: 23 | BW464: 0 | BX464: 10 | BY464: 19 | BZ464: 6

Sheet 100 percent stain
A1: maximum intensity (a.u.) | B1: =MAX(B3:B463) -> 4431.42
B2: Average intensity of 50 pixels for each wavelength (a.u.) | C2: Wavelength (nm) | D2: Raw spectra data from points on the image. All points are taken from biomass
B3: =AVERAGE(D3:BA3) -> 15.42 | C3: 399.9241 | D3: 8 | E3: 13 | F3: 28 | G3: 38 | H3: 40 | I3: 28 | J3: 20 | K3: 22 | L3: 15 | M3: 50 | N3: 23 | O3: 27 | P3: 25 | Q3: -3 | R3: 4 | S3: 22 | T3: 9 | U3: 2 | V3: 34 | W3: 1 | X3: 24 | Y3: 14 | Z3: -6 | AA3: 23 | AB3: 17 | AC3: 4 | AD3: 14 | AE3: -12 | AF3: 7 | AG3: 6 | AH3: 12 | AI3: 22 | AJ3: 12 | AK3: -4 | AL3: 3 | AM3: 5 | AN3: 10 | AO3: 7 | AP3: 18 | AQ3: 7 | AR3: 10 | AS3: 13 | AT3: 13 | AU3: 1 | AV3: 1 | AW3: 38 | AX3: 32 | AY3: 18 | AZ3: 20 | BA3: 36 | BB3: 11 | BC3: 20 | BD3: 28 | BE3: 15 | BF3: 15 | BG3: 9 | BH3: 8 | BI3: 0 | BJ3: 29 | BK3: 14 | BL3: 4 | BM3: 8 | BN3: 23 | BO3: 11 | BP3: 34 | BQ3: 23 | BR3: 10 | BS3: 21
B4: =AVERAGE(D4:BA4) -> 13.48 | C4: 401.12 | D4: 11 | E4: 6 | F4: 14 | G4: 38 | H4: 18 | I4: 8 | J4: 19 | K4: 11 | L4: 46 | M4: 42 | N4: 35 | O4: 3 | P4: 19 | Q4: -9 | R4: -4 | S4: -4 | T4: 5 | U4: 24 | V4: 9 | W4: 29 | X4: 14 | Y4: 0 | Z4: 12 | AA4: 30 | AB4: -3 | AC4: 6 | AD4: 4 | AE4: 10 | AF4: -2 | AG4: -5 | AH4: -2 | AI4: -4 | AJ4: 8 | AK4: 10 | AL4: 1 | AM4: 2 | AN4: 14 | AO4: 3 | AP4: 17 | AQ4: 9 | AR4: 16 | AS4: -1 | AT4: 6 | AU4: 0 | AV4: 11 | AW4: 69 | AX4: 54 | AY4: 20 | AZ4: 30 | BA4: 25 | BB4: 9 | BC4: 28 | BD4: 27 | BE4: 8 | BF4: 15 | BG4: 31 | BH4: 28 | BI4: 7 | BJ4: 27 | BK4: 7 | BL4: 10 | BM4: 14 | BN4: 9 | BO4: 23 | BP4: 18 | BQ4: 35 | BR4: 13 | BS4: 12
